Workbook

Sheet EB-VT
R6: VT | S6: Q [kJ.h^-1] | T6: Q [MJ.h^-1] | U6: Q [kW] | W6: =E46*F46/E25/F25 -> 0.99673895
Q7: Q1 | R7: H-1 | S7: =S26-S25-S34 -> 74053.318 | T7: =S7/1000 -> 74.053318 | U7: =T7/3.6 -> 20.570366 | W7: =E46*G46/E25/G25 -> 0.003227137
Q8: Q2 | R8: H-2 | S8: =S30-S29 -> 142763.77 | T8: =S8/1000 -> 142.76377 | U8: =T8/3.6 -> 39.656603
Q9: Q3 | R9: K-1 | S9: =S32-S33 -> 196496.24 | T9: =S9/1000 -> 196.49624 | U9: =T9/3.6 -> 54.582288
Q10: Q4 | R10: D-1 | S10: =S36+S39-S35 -> 418472.78 | T10: =S10/1000 -> 418.47278 | U10: =T10/3.6 -> 116.24244
Q11: Q5 | R11: K-2 | S11: =S36-S37 -> 437876.3 | T11: =S11/1000 -> 437.8763 | U11: =T11/3.6 -> 121.63231
Q12: Q6 | R12: D-2 | S12: =S44+S47-S42-S43 -> 385782.39 | T12: =S12/1000 -> 385.78239 | U12: =T12/3.6 -> 107.16177
Q13: Q7 | R13: K-3 | S13: =S44-S45 -> 436592.3 | T13: =S13/1000 -> 436.5923 | U13: =T13/3.6 -> 121.27564
Q16: t | R16: =(E25*M25*D25+D34*E34*M34)/(E25*M25+E34*M34) -> 299.89225 | S16: =R16-273.15 -> 26.742248
R19: =EXP(F40*LN(0.55)+G40*LN(0.35)+H40*LN(355)) -> 309.1044 | U19: 44.566995
A20: Referencny stav | C20: L | D20: 273.15 | E20: K | U20: 317.717
U21: 13.480313
U22: 0.99685982
F23: xi | J23: cp(L) [kJ/kmol/K] | N23: ∆vypH [kJ/kmol] | U23: 0.00046882287
A24: Prud | B24: Stav | C24: Teplota [C] | D24: Teplota [K] | E24: n[kmol/h] | F24: A | G24: B | H24: C | I24: Tstred [K] | J24: A | K24: B | L24: C | M24: cp(L) zmes | N24: A | O24: B | P24: C | Q24: ∆vypH zmes | R24: h [kJ/kmol] | S24: H [kJ.h^-1] | U24: 0.0026713605
A25: 1 | B25: L | C25: 25 | D25: =C25+273.15 -> 298.15 | E25: 25 | F25: 0.54 | G25: 0.46 | H25: 0 | I25: =(D25+$D$20)/2 -> 285.65 | J25: 187.5 | K25: =$A$57+$B$57*I25+$C$57*I25^2+$D$57*I25^3 -> 78.91056 | L25: =$A$61+$B$61*I25+$C$61*I25^2 -> 290.55414 | M25: =F25*J25+G25*K25+H25*L25 -> 137.54886 | R25: =M25*(D25-$D$20) -> 3438.7214 | S25: =R25*E25 -> 85968.036
A26: 2,3 | B26: L | C26: 45 | D26: =C26+273.15 -> 318.15 | E26: 30.499721 | F26: 0.47577272 | G26: 0.52422728 | H26: 0 | I26: =(D26+$D$20)/2 -> 295.65 | J26: 187.5 | K26: =$A$57+$B$57*I26+$C$57*I26^2+$D$57*I26^3 -> 80.988006 | L26: =$A$61+$B$61*I26+$C$61*I26^2 -> 292.98104 | M26: =F26*J26+G26*K26+H26*L26 -> 131.66351 | R26: =M26*(D26-$D$20) -> 5924.8578 | S26: =R26*E26 -> 180706.51
A27: 4 | B27: L | C27: 45 | D27: =C27+273.15 -> 318.15 | E27: 0 | F27: 0 | G27: 0 | H27: 1 | I27: =(D27+$D$20)/2 -> 295.65 | J27: 187.5 | K27: =$A$57+$B$57*I27+$C$57*I27^2+$D$57*I27^3 -> 80.988006 | L27: =$A$61+$B$61*I27+$C$61*I27^2 -> 292.98104 | M27: =F27*J27+G27*K27+H27*L27 -> 292.98104 | R27: =M27*(D27-$D$20) -> 13184.147 | S27: =R27*E27 -> 0
A28: 5 | B28: L | C28: 45 | D28: =C28+273.15 -> 318.15 | E28: 12.161668 | F28: 0.0015585105 | G28: 0.019958852 | H28: 0.97848264 | I28: =(D28+$D$20)/2 -> 295.65 | J28: 187.5 | K28: =$A$57+$B$57*I28+$C$57*I28^2+$D$57*I28^3 -> 80.988006 | L28: =$A$61+$B$61*I28+$C$61*I28^2 -> 292.98104 | M28: =F28*J28+G28*K28+H28*L28 -> 288.58551 | R28: =M28*(D28-$D$20) -> 12986.348 | S28: =R28*E28 -> 157935.66
A29: 6 | B29: L | C29: 45 | D29: =C29+273.15 -> 318.15 | E29: 29.141976 | F29: 0.036193375 | G29: 0.40812862 | H29: 0.55567801 | I29: =(D29+$D$20)/2 -> 295.65 | J29: 187.5 | K29: =$A$57+$B$57*I29+$C$57*I29^2+$D$57*I29^3 -> 80.988006 | L29: =$A$61+$B$61*I29+$C$61*I29^2 -> 292.98104 | M29: =F29*J29+G29*K29+H29*L29 -> 202.6429 | R29: =M29*(D29-$D$20) -> 9118.9305 | S29: =R29*E29 -> 265743.65
A30: 7 | B30: L | C30: 68 | D30: =C30+273.15 -> 341.15 | E30: 29.141976 | F30: 0.036193375 | G30: 0.40812862 | H30: 0.55567801 | I30: =(D30+$D$20)/2 -> 307.15 | J30: 187.5 | K30: =$A$57+$B$57*I30+$C$57*I30^2+$D$57*I30^3 -> 83.647247 | L30: =$A$61+$B$61*I30+$C$61*I30^2 -> 297.32965 | M30: =F30*J30+G30*K30+H30*L30 -> 206.14464 | R30: =M30*(D30-$D$20) -> 14017.835 | S30: =R30*E30 -> 408507.42
U31: 5.4988377 | V31: ng
A32: 9 | B32: G | C32: 45.114109 | D32: =C32+273.15 -> 318.26411 | E32: 5.4988377 | F32: 0.18383745 | G32: 0.81616255 | H32: 0 | I32: =(D32+$D$20)/2 -> 295.70705 | J32: 187.5 | K32: =$A$57+$B$57*I32+$C$57*I32^2+$D$57*I32^3 -> 81.000485 | L32: =$A$61+$B$61*I32+$C$61*I32^2 -> 292.9985 | M32: =F32*J32+G32*K32+H32*L32 -> 100.57908 | N32: =$N$54*1000*EXP(-$N$55*D32/$N$56)*(1-D32/$N$56)^$N$55 -> 28578.34 | O32: =$G$53*1000*EXP(-$G$54*D32/$G$56)*(1-D32/$G$56)^$G$55 -> 36395.406 | P32: 0 | Q32: =N32*F32+O32*G32 -> 34958.337 | R32: =M32*(D32-$D$20)+Q32 -> 39495.873 | S32: =R32*E32 -> 217181.4 | U32: 0.18383745 | V32: a
A33: 10 | B33: L | C33: 37.645679 | D33: =C33+273.15 -> 310.79568 | E33: 5.4988377 | F33: 0.18383745 | G33: 0.81616255 | H33: 0 | I33: =(D33+$D$20)/2 -> 291.97284 | J33: 187.5 | K33: =$A$57+$B$57*I33+$C$57*I33^2+$D$57*I33^3 -> 80.198681 | L33: =$A$61+$B$61*I33+$C$61*I33^2 -> 291.94215 | M33: =F33*J33+G33*K33+H33*L33 -> 99.924682 | R33: =M33*(D33-$D$20) -> 3761.7325 | S33: =R33*E33 -> 20685.157 | U33: 0.81616255 | V33: b
A34: 11 | B34: L | C34: 37.645679 | D34: =C34+273.15 -> 310.79568 | E34: 5.4988377 | F34: 0.18383745 | G34: 0.81616255 | H34: 0 | I34: =(D34+$D$20)/2 -> 291.97284 | J34: 187.5 | K34: =$A$57+$B$57*I34+$C$57*I34^2+$D$57*I34^3 -> 80.198681 | L34: =$A$61+$B$61*I34+$C$61*I34^2 -> 291.94215 | M34: =F34*J34+G34*K34+H34*L34 -> 99.924682 | R34: =M34*(D34-$D$20) -> 3761.7325 | S34: =R34*E34 -> 20685.157 | U34: 0 | V34: c
A35: 12 | B35: L | C35: 45.114109 | D35: =C35+273.15 -> 318.26411 | E35: 23.642682 | F35: 0.0018542192 | G35: 0.49508689 | H35: 0.5030589 | I35: =(D35+$D$20)/2 -> 295.70705 | J35: 187.5 | K35: =$A$57+$B$57*I35+$C$57*I35^2+$D$57*I35^3 -> 81.000485 | L35: =$A$61+$B$61*I35+$C$61*I35^2 -> 292.9985 | M35: =F35*J35+G35*K35+H35*L35 -> 187.84545 | R35: =M35*(D35-$D$20) -> 8474.4798 | S35: =R35*E35 -> 200359.43
A36: 13 | B36: G | C36: 45.124085 | D36: =C36+273.15 -> 318.27408 | E36: 11.506293 | F36: 0.0038097301 | G36: 0.99619026 | H36: 0 | I36: =(D36+$D$20)/2 -> 295.71204 | J36: 187.5 | K36: =$A$57+$B$57*I36+$C$57*I36^2+$D$57*I36^3 -> 81.001577 | L36: =$A$61+$B$61*I36+$C$61*I36^2 -> 293.00003 | M36: =F36*J36+G36*K36+H36*L36 -> 81.407306 | N36: =$N$54*1000*EXP(-$N$55*D36/$N$56)*(1-D36/$N$56)^$N$55 -> 28577.713 | O36: =$G$53*1000*EXP(-$G$54*D36/$G$56)*(1-D36/$G$56)^$G$55 -> 36394.834 | P36: 0 | Q36: =N36*F36+O36*G36 -> 36365.052 | R36: =M36*(D36-$D$20)+Q36 -> 40038.482 | S36: =R36*E36 -> 460694.51
A37: 14 | B37: L | C37: 25 | D37: =C37+273.15 -> 298.15 | E37: 11.506293 | F37: 0.0038097301 | G37: 0.99619026 | H37: 0 | I37: =(D37+$D$20)/2 -> 285.65 | J37: 187.5 | K37: =$A$57+$B$57*I37+$C$57*I37^2+$D$57*I37^3 -> 78.91056 | L37: =$A$61+$B$61*I37+$C$61*I37^2 -> 290.55414 | M37: =F37*J37+G37*K37+H37*L37 -> 79.324256 | R37: =M37*(D37-$D$20) -> 1983.1064 | S37: =R37*E37 -> 22818.203
A38: 15 | B38: L | C38: 25 | D38: =C38+273.15 -> 298.15 | E38: 11.506293 | F38: 0.0038097301 | G38: 0.99619026 | H38: 0 | I38: =(D38+$D$20)/2 -> 285.65 | J38: 187.5 | K38: =$A$57+$B$57*I38+$C$57*I38^2+$D$57*I38^3 -> 78.91056 | L38: =$A$61+$B$61*I38+$C$61*I38^2 -> 290.55414 | M38: =F38*J38+G38*K38+H38*L38 -> 79.324256 | R38: =M38*(D38-$D$20) -> 1983.1064 | S38: =R38*E38 -> 22818.203
A39: 16 | B39: L | C39: 45.124085 | D39: =C39+273.15 -> 318.27408 | E39: 12.1364 | F39: 2.3429567e-07 | G39: 0.01999977 | H39: 0.98 | I39: =(D39+$D$20)/2 -> 295.71204 | J39: 187.5 | K39: =$A$57+$B$57*I39+$C$57*I39^2+$D$57*I39^3 -> 81.001577 | L39: =$A$61+$B$61*I39+$C$61*I39^2 -> 293.00003 | M39: =F39*J39+G39*K39+H39*L39 -> 288.76008 | R39: =M39*(D39-$D$20) -> 13030.034 | S39: =R39*E39 -> 158137.71
A40: 17 | B40: L | C40: 45.124085 | D40: =C40+273.15 -> 318.27408 | E40: 12.1364 | F40: 2.3429567e-07 | G40: 0.01999977 | H40: 0.98 | I40: =(D40+$D$20)/2 -> 295.71204 | J40: 187.5 | K40: =$A$57+$B$57*I40+$C$57*I40^2+$D$57*I40^3 -> 81.001577 | L40: =$A$61+$B$61*I40+$C$61*I40^2 -> 293.00003 | M40: =F40*J40+G40*K40+H40*L40 -> 288.76008 | R40: =M40*(D40-$D$20) -> 13030.034 | S40: =R40*E40 -> 158137.71
A41: 18 | B41: L | C41: 45 | D41: =C41+273.15 -> 318.15 | E41: 13.518541 | F41: 0.9967866 | G41: 0.00046749714 | H41: 0.0027458997 | I41: =(D41+$D$20)/2 -> 295.65 | J41: 187.5 | K41: =$A$57+$B$57*I41+$C$57*I41^2+$D$57*I41^3 -> 80.988006 | L41: =$A$61+$B$61*I41+$C$61*I41^2 -> 292.98104 | M41: =F41*J41+G41*K41+H41*L41 -> 187.73985 | R41: =M41*(D41-$D$20) -> 8448.2931 | S41: =R41*E41 -> 114208.59
A42: 19 | B42: L | C42: 44.566995 | D42: =C42+273.15 -> 317.717 | E42: 13.480313 | F42: 0.99685982 | G42: 0.00046882287 | H42: 0.0026713605 | I42: =(D42+$D$20)/2 -> 295.4335 | J42: 187.5 | K42: =$A$57+$B$57*I42+$C$57*I42^2+$D$57*I42^3 -> 80.940713 | L42: =$A$61+$B$61*I42+$C$61*I42^2 -> 292.91515 | M42: =F42*J42+G42*K42+H42*L42 -> 187.73164 | R42: =M42*(D42-$D$20) -> 8366.6353 | S42: =R42*E42 -> 112784.86 | U42: 0.038227615 | V42: ng
A43: 19 | B43: G | C43: 44.566995 | D43: =C43+273.15 -> 317.717 | E43: 0.038227615 | F43: 0.97096914 | G43: 0.029030861 | H43: 0 | I43: =(D43+$D$20)/2 -> 295.4335 | J43: 187.5 | K43: =$A$57+$B$57*I43+$C$57*I43^2+$D$57*I43^3 -> 80.940713 | L43: =$A$61+$B$61*I43+$C$61*I43^2 -> 292.91515 | M43: =F43*J43+G43*K43+H43*L43 -> 184.40649 | N43: =$N$54*1000*EXP(-$N$55*D43/$N$56)*(1-D43/$N$56)^$N$55 -> 28612.715 | O43: =$G$53*1000*EXP(-$G$54*D43/$G$56)*(1-D43/$G$56)^$G$55 -> 36426.772 | P43: 0 | Q43: =N43*F43+O43*G43 -> 28839.564 | R43: =M43*(D43-$D$20)+Q43 -> 37058.007 | S43: =R43*E43 -> 1416.6392 | U43: 0.97096914 | V43: a
A44: 20 | B44: G | C44: 45.043753 | D44: =C44+273.15 -> 318.19375 | E44: 13.493088 | F44: 0.99724955 | G44: 0.0027504509 | H44: 0 | I44: =(D44+$D$20)/2 -> 295.67188 | J44: 187.5 | K44: =$A$57+$B$57*I44+$C$57*I44^2+$D$57*I44^3 -> 80.99279 | L44: =$A$61+$B$61*I44+$C$61*I44^2 -> 292.98773 | M44: =F44*J44+G44*K44+H44*L44 -> 187.20706 | N44: =$N$54*1000*EXP(-$N$55*D44/$N$56)*(1-D44/$N$56)^$N$55 -> 28582.763 | O44: =$G$53*1000*EXP(-$G$54*D44/$G$56)*(1-D44/$G$56)^$G$55 -> 36399.445 | P44: 0 | Q44: =N44*F44+O44*G44 -> 28604.262 | R44: =M44*(D44-$D$20)+Q44 -> 37036.771 | S44: =R44*E44 -> 499740.4 | U44: 0.029030861 | V44: b
A45: 21 | B45: L | C45: 25 | D45: =C45+273.15 -> 298.15 | E45: 13.493088 | F45: 0.99724955 | G45: 0.0027504509 | H45: 0 | I45: =(D45+$D$20)/2 -> 285.65 | J45: 187.5 | K45: =$A$57+$B$57*I45+$C$57*I45^2+$D$57*I45^3 -> 78.91056 | L45: =$A$61+$B$61*I45+$C$61*I45^2 -> 290.55414 | M45: =F45*J45+G45*K45+H45*L45 -> 187.20133 | R45: =M45*(D45-$D$20) -> 4680.0333 | S45: =R45*E45 -> 63148.1 | U45: 0 | V45: c
A46: 22 | B46: L | C46: 25 | D46: =C46+273.15 -> 298.15 | E46: 13.493088 | F46: 0.99724955 | G46: 0.0027504509 | H46: 0 | I46: =(D46+$D$20)/2 -> 285.65 | J46: 187.5 | K46: =$A$57+$B$57*I46+$C$57*I46^2+$D$57*I46^3 -> 78.91056 | L46: =$A$61+$B$61*I46+$C$61*I46^2 -> 290.55414 | M46: =F46*J46+G46*K46+H46*L46 -> 187.20133 | R46: =M46*(D46-$D$20) -> 4680.0333 | S46: =R46*E46 -> 63148.1
A47: 23 | B47: L | C47: 45.043753 | D47: =C47+273.15 -> 318.19375 | E47: 0.025279191 | F47: 0.74968563 | G47: 0.00031437215 | H47: 0.25 | I47: =(D47+$D$20)/2 -> 295.67188 | J47: 187.5 | K47: =$A$57+$B$57*I47+$C$57*I47^2+$D$57*I47^3 -> 80.99279 | L47: =$A$61+$B$61*I47+$C$61*I47^2 -> 292.98773 | M47: =F47*J47+G47*K47+H47*L47 -> 213.83845 | R47: =M47*(D47-$D$20) -> 9632.0862 | S47: =R47*E47 -> 243.49135
A48: 24 | B48: L | C48: 45.043753 | D48: =C48+273.15 -> 318.19375 | E48: 0.025279191 | F48: 0.74968563 | G48: 0.00031437215 | H48: 0.25 | I48: =(D48+$D$20)/2 -> 295.67188 | J48: 187.5 | K48: =$A$57+$B$57*I48+$C$57*I48^2+$D$57*I48^3 -> 80.99279 | L48: =$A$61+$B$61*I48+$C$61*I48^2 -> 292.98773 | M48: =F48*J48+G48*K48+H48*L48 -> 213.83845 | R48: =M48*(D48-$D$20) -> 9632.0862 | S48: =R48*E48 -> 243.49135
A51: A | B51: MTBE
...

Sheet cerpadla
A1: Cerpadla | B1: Tlak [kPa] | D1: vyska | E1: Prudy
B2: z | C2: do | D2: Δz [m] | J2: M[kg/kmol]
A3: P-1 | B3: 101.325 | C3: 101.325 | D3: 5 | E3: 2,18 | G3: A | H3: MTBE | I3: 1 | J3: 88.15
A4: P-2 | B4: 50 | C4: 101.325 | D4: 0 | E4: 10,11 | G4: B | H4: Metanol | I4: 2 | J4: 32.04
A5: P-3 | B5: 2.45 | C5: 101.325 | D5: 0 | E5: 14,15 | G5: C | H5: [BMIM][HSO4] | I5: 3 | J5: 236.29
A6: P-4 | B6: 2.45 | C6: 101.325 | D6: 5 | E6: 16,17
A7: P-5 | B7: 73.5 | C7: 101.325 | D7: 0 | E7: 21,22
A8: P-6 | B8: 73.5 | C8: 101.325 | D8: 0 | E8: 23,24
A10: Cerpadlo | B10: n[kmol/h] | C10: xA | D10: xB | E10: xC | F10: M[kg/kmol] | G10: m[ kg/h] | H10: wA | I10: wB | J10: wC | K10: sumW | L10: Teplota [C] | M10: Teplota [K] | N10: rhoA [kg/m3] | O10: rhoB [kg/m3] | P10: rhoC [kg/m3] | Q10: rho zmes | R10: V [m3/h] | S10: V [m3/s]
A11: P-1 | B11: 30.499721 | C11: 0.47577272 | D11: 0.52422728 | E11: 0 | F11: =C11*$J$3+D11*$J$4+E11*$J$5 -> 58.735607 | G11: =B11*F11 -> 1791.4196 | H11: =(C11*$J$3)/F11 -> 0.71403646 | I11: =(D11*$J$4)/F11 -> 0.28596354 | J11: =(E11*$J$5)/F11 -> 0 | K11: =SUM(H11:J11) -> 1 | L11: 45 | M11: =L11+273.15 -> 318.15 | N11: =FORECAST(L11,R40:R41,O40:O41) -> 713.84 | O11: =FORECAST(L11,B37:B38,A37:A38) -> 767.5 | P11: =FORECAST(L11,H39:H40,D39:D40) -> 1266.31 | Q11: =H11*N11+I11*O11+J11*P11 -> 729.1848 | R11: =G11/Q11 -> 2.456743 | S11: =R11/3600 -> 0.0006824286
A12: P-2 | B12: 5.4988377 | C12: 0.18383745 | D12: 0.81616255 | E12: 0 | F12: =C12*$J$3+D12*$J$4+E12*$J$5 -> 42.355119 | G12: =B12*F12 -> 232.90393 | H12: =(C12*$J$3)/F12 -> 0.38260478 | I12: =(D12*$J$4)/F12 -> 0.61739522 | J12: =(E12*$J$5)/F12 -> 0 | K12: =SUM(H12:J12) -> 1 | L12: 37.645679 | M12: =L12+273.15 -> 310.79568 | N12: =FORECAST(L12,R39:R40,O39:O40) -> 721.83267 | O12: =FORECAST(L12,B36:B37,A36:A37) -> 774.35432 | P12: =FORECAST(L12,H37:H38,D37:D38) -> 1270.543 | Q12: =H12*N12+I12*O12+J12*P12 -> 754.25928 | R12: =G12/Q12 -> 0.30878497 | S12: =R12/3600 -> 8.5773602e-05
A13: P-3 | B13: 11.506293 | C13: 0.0038097301 | D13: 0.99619026 | E13: 0 | F13: =C13*$J$3+D13*$J$4+E13*$J$5 -> 32.253764 | G13: =B13*F13 -> 371.12125 | H13: =(C13*$J$3)/F13 -> 0.010412047 | I13: =(D13*$J$4)/F13 -> 0.98958795 | J13: =(E13*$J$5)/F13 -> 0 | K13: =SUM(H13:J13) -> 1 | L13: 25 | M13: =L13+273.15 -> 298.15 | N13: =FORECAST(L13,R36:R37,O36:O37) -> 735.34 | O13: =FORECAST(L13,B35:B36,A35:A36) -> 786.5 | P13: 1277 | Q13: =H13*N13+I13*O13+J13*P13 -> 785.96732 | R13: =G13/Q13 -> 0.47218407 | S13: =R13/3600 -> 0.00013116224
A14: P-4 | B14: 12.1364 | C14: 2.3429567e-07 | D14: 0.01999977 | E14: 0.98 | F14: =C14*$J$3+D14*$J$4+E14*$J$5 -> 232.20501 | G14: =B14*F14 -> 2818.1328 | H14: =(C14*$J$3)/F14 -> 8.8943658e-08 | I14: =(D14*$J$4)/F14 -> 0.0027595986 | J14: =(E14*$J$5)/F14 -> 0.99724031 | K14: =SUM(H14:J14) -> 1 | L14: 45.124085 | M14: =L14+273.15 -> 318.27408 | N14: =FORECAST(L14,R41:R42,O41:O42) -> 713.70624 | O14: =FORECAST(L14,B37:B38,A37:A38) -> 767.38832 | P14: =FORECAST(L14,H39:H40,D39:D40) -> 1266.2355 | Q14: =H14*N14+I14*O14+J14*P14 -> 1264.8589 | R14: =G14/Q14 -> 2.2280216 | S14: =R14/3600 -> 0.00061889488
A15: P-5 | B15: 13.493088 | C15: 0.99724955 | D15: 0.0027504509 | E15: 0 | F15: =C15*$J$3+D15*$J$4+E15*$J$5 -> 87.995672 | G15: =B15*F15 -> 1187.3333 | H15: =(C15*$J$3)/F15 -> 0.99899854 | I15: =(D15*$J$4)/F15 -> 0.0010014634 | J15: =(E15*$J$5)/F15 -> 0 | K15: =SUM(H15:J15) -> 1 | L15: 25 | M15: =L15+273.15 -> 298.15 | N15: =FORECAST(L15,R36:R37,O36:O37) -> 735.34 | O15: =FORECAST(L15,B35:B36,A35:A36) -> 786.5 | P15: 1277 | Q15: =H15*N15+I15*O15+J15*P15 -> 735.39123 | R15: =G15/Q15 -> 1.6145601 | S15: =R15/3600 -> 0.00044848891
A16: P-6 | B16: 0.025279191 | C16: 0.74968563 | D16: 0.00031437215 | E16: 0.25 | F16: =C16*$J$3+D16*$J$4+E16*$J$5 -> 125.16736 | G16: =B16*F16 -> 3.1641296 | H16: =(C16*$J$3)/F16 -> 0.52797141 | I16: =(D16*$J$4)/F16 -> 8.0472126e-05 | J16: =(E16*$J$5)/F16 -> 0.47194812 | K16: =SUM(H16:J16) -> 1 | L16: 45.043753 | M16: =L16+273.15 -> 318.19375 | N16: =FORECAST(L16,R40:R41,O40:O41) -> 713.79231 | O16: =FORECAST(L16,B37:B38,A37:A38) -> 767.46062 | P16: =FORECAST(L16,H39:H40,D39:D40) -> 1266.2837 | Q16: =H16*N16+I16*O16+J16*P16 -> 974.54392 | R16: =G16/Q16 -> 0.0032467799 | S16: =R16/3600 -> 9.0188329e-07
E18: Tlak [Pa]
A19: Cerpadlo | B19: V [m3/s] | C19: m[ kg/s] | D19: rho zmes [kg/m3] | E19: z | F19: do | G19: Δz [m] | H19: Edis [J/kg] | I19: Ew [J/kg] | J19: Pv [W] | K19: η | L19: Pp
A20: P-1 | B20: =S11 -> 0.0006824286 | C20: =G11/3600 -> 0.49761657 | D20: =Q11 -> 729.1848 | E20: =B3*1000 -> 101325 | F20: =C3*1000 -> 101325 | G20: 5 | H20: 3.5 | I20: =(F20-E20)/D20+G20*9.81+H20 -> 52.55 | J20: =B20*D20*I20 -> 26.149751 | K20: 0.7 | L20: =J20/K20 -> 37.356786
A21: P-2 | B21: =S12 -> 8.5773602e-05 | C21: =G12/3600 -> 0.064695536 | D21: =Q12 -> 754.25928 | E21: =B4*1000 -> 50000 | F21: =C4*1000 -> 101325 | G21: 1 | H21: 3.5 | I21: =(F21-E21)/D21+G21*9.81+H21 -> 81.356892 | J21: =B21*D21*I21 -> 5.2634277 | K21: 0.7 | L21: =J21/K21 -> 7.5191824
A22: P-3 | B22: =S13 -> 0.00013116224 | C22: =G13/3600 -> 0.10308924 | D22: =Q13 -> 785.96732 | E22: =B5*1000 -> 2450 | F22: =C5*1000 -> 101325 | G22: 1 | H22: 3.5 | I22: =(F22-E22)/D22+G22*9.81+H22 -> 139.1104 | J22: =B22*D22*I22 -> 14.340784 | K22: 0.7 | L22: =J22/K22 -> 20.486835
A23: P-4 | B23: =S14 -> 0.00061889488 | C23: =G14/3600 -> 0.78281468 | D23: =Q14 -> 1264.8589 | E23: =B6*1000 -> 2450 | F23: =C6*1000 -> 101325 | G23: 5 | H23: 3.5 | I23: =(F23-E23)/D23+G23*9.81+H23 -> 130.72078 | J23: =B23*D23*I23 -> 102.33014 | K23: 0.7 | L23: =J23/K23 -> 146.18592
A24: P-5 | B24: =S15 -> 0.00044848891 | C24: =G15/3600 -> 0.32981482 | D24: =Q15 -> 735.39123 | E24: =B7*1000 -> 73500 | F24: =C7*1000 -> 101325 | G24: 0.5 | H24: 3.5 | I24: =(F24-E24)/D24+G24*9.81+H24 -> 46.242003 | J24: =B24*D24*I24 -> 15.251298 | K24: 0.7 | L24: =J24/K24 -> 21.787568
A25: P-6 | B25: =S16 -> 9.0188329e-07 | C25: =G16/3600 -> 0.00087892488 | D25: =Q16 -> 974.54392 | E25: =B8*1000 -> 73500 | F25: =C8*1000 -> 101325 | G25: 2 | H25: 3.5 | I25: =(F25-E25)/D25+G25*9.81+H25 -> 51.671817 | J25: =B25*D25*I25 -> 0.045415646 | K25: 0.7 | L25: =J25/K25 -> 0.064879494
A32: Tabulky CHI | E32: [BMIM][HSO4] | P32: MTBE | Q32: https://www.chemeo.com/cid/50-231-9/Propane-2-methoxy-2-methyl
A33: MEeOH | E33: Temperature, K | F33: Pressure, kPa | G33: Specific density, kg/m3 | P33: Temperature, K | Q33: Pressure, kPa | R33: Mass density, kg/m3 - Liquid
A34: Teplota [C] | B34: rho [kg/m3] | G34: Liquid | O34: =P34-273.15 -> 10 | P34: 283.15 | Q34: 100 | R34: 750.94
A35: 20 | B35: 791 | D35: =E35-273.15 -> 24.95 | E35: 298.1 | F35: 101.325 | G35: 1277 ± 1 | H35: 1277 | I35: Jain, P.; Kumar, A. (2017) J. Mol. Liq. 238, 270-280. | O35: =P35-273.15 -> 15 | P35: 288.15 | Q35: 100 | R35: 745.79
A36: 30 | B36: 782 | D36: =E36-273.15 -> 29.85 | E36: 303 | F36: 101.325 | G36: 1275.9 ± 0.4 | H36: =1275.9 -> 1275.9 | O36: =P36-273.15 -> 20 | P36: 293.15 | Q36: 100 | R36: 740.59
A37: 40 | B37: 772 | D37: =E37-273.15 -> 34.85 | E37: 308 | F37: 101.325 | G37: 1272.5 ± 0.4 | H37: 1272.5 | O37: =P37-273.15 -> 25 | P37: 298.15 | Q37: 100 | R37: 735.34
A38: 50 | B38: 763 | D38: =E38-273.15 -> 39.85 | E38: 313 | F38: 101.325 | G38: 1269 ± 0.4 | H38: 1269 | O38: =P38-273.15 -> 30 | P38: 303.15 | Q38: 100 | R38: 730.04
D39: =E39-273.15 -> 44.85 | E39: 318 | F39: 101.325 | G39: 1266.4 ± 0.4 | H39: 1266.4 | O39: =P39-273.15 -> 35 | P39: 308.15 | Q39: 100 | R39: 724.69
D40: =E40-273.15 -> 49.85 | E40: 323 | F40: 101.325 | G40: 1263.4 ± 0.4 | H40: 1263.4 | O40: =P40-273.15 -> 40 | P40: 313.15 | Q40: 100 | R40: 719.29
D41: =E41-273.15 -> 54.85 | E41: 328 | F41: 101.325 | G41: 1260.4 ± 0.4 | H41: 1260.4 | O41: =P41-273.15 -> 45 | P41: 318.15 | Q41: 100 | R41: 713.84
D42: =E42-273.15 -> 59.85 | E42: 333 | F42: 101.325 | G42: 1257.4 ± 0.4 | H42: 1257.4 | O42: =P42-273.15 -> 50 | P42: 323.15 | Q42: 100 | R42: 708.45
D43: =E43-273.15 -> 64.85 | E43: 338 | F43: 101.325 | G43: 1254.5 ± 0.4 | H43: 1254.5
D44: =E44-273.15 -> 69.85 | E44: 343 | F44: 101.325 | G44: 1251.5 ± 0.4 | H44: 1251.5
D45: =E45-273.15 -> 74.85 | E45: 348 | F45: 101.325 | G45: 1248.6 ± 0.4 | H45: 1248.6
D46: =E46-273.15 -> 79.85 | E46: 353 | F46: 101.325 | G46: 1245.7 ± 0.4 | H46: 1245.7
D47: =E47-273.15 -> 84.85 | E47: 358 | F47: 101.325 | G47: 1242.8 ± 0.4 | H47: 1242.8
D48: =E48-273.15 -> 89.85 | E48: 363 | F48: 101.325 | G48: 1240 ± 0.4 | H48: 1240
...

Sheet NRTL-binary
A1: https://pubs.acs.org/doi/epdf/10.1021/je950323o?ref=article_openPDF
A4: MTBE (1) | B4: A
A5: Metanol (2) | B5: B | E5: t | F5: T [K] | G5: τ12 | H5: τ21 | I5: G12 | J5: G21 | K5: x1 | L5: x2 | M5: lnγA | N5: lnγB | O5: γA | P5: γB | Q5: PA0 | R5: PB0 | S5: PA | T5: PB | U5: yA | V5: yB | W5: SUMy | X5: sumP
E6: =F6-273.15 -> 37.645679 | F6: 310.79568 | G6: =B8/B11/F6 -> 0.91850274 | H6: =B9/B11/F6 -> 0.61230936 | I6: =EXP(-$B$7*G6) -> 0.64940658 | J6: =EXP(-$B$7*H6) -> 0.74992251 | K6: 0.18383745 | L6: 0.81616255 | M6: =L6^2*(H6*(J6/(K6+L6*J6))^2+G6*I6/(L6+K6*I6)^2) -> 0.81607405 | N6: =K6^2*(G6*(I6/(L6+K6*I6))^2+H6*J6/(K6+L6*J6)^2) -> 0.039455853 | O6: =EXP(M6) -> 2.2616034 | P6: =EXP(N6) -> 1.0402446 | Q6: =EXP(C16+D16/(F6+E16))/1000 -> 55.456167 | R6: =EXP(C17+D17/(F6+E17))/1000 -> 31.734758 | S6: =O6*Q6*K6 -> 23.056867 | T6: =P6*R6*L6 -> 26.943084 | U6: =S6/$B$12 -> 0.46113734 | V6: =T6/$B$12 -> 0.53886169 | W6: =SUM(U6:V6) -> 0.99999903 | X6: =SUM(S6:T6) -> 49.999951
A7: alpha | B7: 0.47
A8: dg12 | B8: 2373.37 | C8: J/mol
A9: dg21 | B9: 1582.18 | C9: J/mol
A11: R | B11: 8.314 | C11: J/mol/K
A12: p | B12: 50 | C12: kPa
C14: Antoine equation parameters (P = Pa)
C15: A | D15: B | E15: C
A16: A | B16: MTBE | C16: 20.84054 | D16: -2624.525 | E16: -46.15171
A17: B | B17: Metanol | C17: 23.5347 | D17: -3661.468 | E17: -32.77001

Sheet Ekonomika
A1: VT | B1: [W] | G1: cenove indexy | K1: extrakcna kolona
A2: Q1 | B2: ='EB-VT'!U7*1000 -> 20570.366 | C2: H-1 | G2: 2002 | H2: 395.6 | K2: material | L2: prierez [m] | M2: vyska [m] | N2: PTK | O2: hrubka steny [m] | P2: hustota materialu [kg/m3]
A3: Q2 | B3: ='EB-VT'!U8*1000 -> 39656.603 | C3: H-2 | G3: 2025 | H3: 785 | K3: Hastelloy C | L3: 1 | M3: 3 | N3: 5 | O3: 0.012 | P3: 8890
A4: Q3 | B4: ='EB-VT'!U9*1000 -> 54582.288 | C4: K-1 | G4: 2024 jun | H4: 798.8
A5: Q4 | B5: ='EB-VT'!U10*1000 -> 116242.44 | C5: D-1 | G5: 2014 | H5: 576.1 | K5: Hmota kolony [kg] | L5: =M3*O3*L3*PI()*P3 -> 1005.4353 | N5: total weight [kg] | O5: =SUM(L5:L8) -> 1602.7725 | Q5: cena(2014) | R5: cena(2025)
A6: Q5 | B6: ='EB-VT'!U11*1000 -> 121632.31 | C6: K-2 | K6: Hlava a dole [kg] | L6: =0.9*PI()*L3^2*O3*P3 -> 301.63059 | N6: [pounds | O6: =O5*2.20462 -> 3533.5043 | Q6: 53300 | R6: =Q6*H3/H5 -> 72627.148
A7: Q6 | B7: ='EB-VT'!U12*1000 -> 107161.77 | C7: D-2 | K7: Tray-Hasteloy [kg] | L7: =30*5 -> 150
A8: Q7 | B8: ='EB-VT'!U13*1000 -> 121275.64 | C8: K-3 | K8: extra | L8: =0.1*(L5+L6+L7) -> 145.70659
B11: Ohrevac-1 | L11: Odparka-1
B12: Protiprúdny výmenník tepla
B13: Q [W] | C13: k [W/m2/K] | D13: tH1 | E13: tH2 | F13: tS1 | G13: tS2 | H13: dtls | I13: A [m2] | J13: A [ft2] | L13: Q [W] | M13: k [W/m2/K] | N13: tH1 | O13: tH2 | P13: tS1 | Q13: tS2 | R13: dtls | S13: A [m2] | T13: A [ft2]
B14: =B2 -> 20570.366 | C14: =100*5.6873 -> 568.73 | D14: 102 | E14: 102 | F14: ='EB-VT'!S16 -> 26.742248 | G14: 45 | H14: =((D14-G14)-(E14-F14))/LN((D14-G14)/(E14-F14)) -> 65.706649 | I14: =B14/C14/H14 -> 0.55046101 | J14: =10.7639104167*I14 -> 5.925113 | L14: =B5 -> 116242.44 | M14: 300 | N14: 102 | O14: 102 | P14: ='EB-VT'!C35 -> 45.114109 | Q14: ='EB-VT'!C36 -> 45.124085 | R14: =((N14-Q14)-(O14-P14))/LN((N14-Q14)/(O14-P14)) -> 56.880903 | S14: =L14/M14/R14 -> 6.8120366 | T14: =10.7639104167*S14 -> 73.324151
B17: Ohrevac-2 | L17: Odparka-2
B18: Protiprúdny výmenník tepla
B19: Q [W] | C19: k [W/m2/K] | D19: tH1 | E19: tH2 | F19: tS1 | G19: tS2 | H19: dtls | I19: A [m2] | J19: A [ft2] | L19: Q [W] | M19: k [W/m2/K] | N19: tH1 | O19: tH2 | P19: tS1 | Q19: tS2 | R19: dtls | S19: A [m2] | T19: A [ft2]
B20: =B3 -> 39656.603 | C20: 75 | D20: 102 | E20: 102 | F20: 45 | G20: 68 | H20: =((D20-G20)-(E20-F20))/LN((D20-G20)/(E20-F20)) -> 44.514055 | I20: =B20/C20/H20 -> 11.878377 | J20: =10.7639104167*I20 -> 127.85778 | L20: =B7 -> 107161.77 | M20: 300 | N20: 102 | O20: 102 | P20: ='EB-VT'!C42 -> 44.566995 | Q20: ='EB-VT'!C44 -> 45.043753 | R20: =((N20-Q20)-(O20-P20))/LN((N20-Q20)/(O20-P20)) -> 57.194295 | S20: =L20/M20/R20 -> 6.2454816 | T20: =10.7639104167*S20 -> 67.225804
B23: Kondenzator-1
B24: Protiprúdny výmenník tepla | L24: Spotreba ohrevnej pary | R24: Spotreba chladiacej vody
B25: Q [W] | C25: k [W/m2/K] | D25: tH1 | E25: tH2 | F25: tS1 | G25: tS2 | H25: dtls | I25: A [m2] | J25: A [ft2] | L25: Q1 [W] | M25: dVapH [J/kg] | N25: mOP [kg/s] | O25: mOP [kg/h] | R25: Q3 [W] | S25: cpV [J//kg/K] | T25: mV [kg/s] | U25: mV [kg/h]
B26: =B4 -> 54582.288 | C26: =150*5.6873 -> 853.095 | D26: ='EB-VT'!C32 -> 45.114109 | E26: ='EB-VT'!C33 -> 37.645679 | F26: 15 | G26: 35 | H26: =((D26-G26)-(E26-F26))/LN((D26-G26)/(E26-F26)) -> 15.547127 | I26: =B26/C26/H26 -> 4.1153256 | J26: =10.7639104167*I26 -> 44.296997 | L26: =B2 -> 20570.366 | M26: =2252*1000 -> 2252000 | N26: =L26/M26 -> 0.0091342655 | O26: =N26*1000 -> 9.1342655 | R26: =B3 -> 39656.603 | S26: 4190 | T26: =R26/S26/(G26-F26) -> 0.47322915 | U26: =T26*1000 -> 473.22915
L27: Q2 [W] | M27: dVapH [J/kg] | N27: mOP [kg/s] | O27: mOP [kg/h] | R27: Q5 [W] | S27: cpV [J//kg/K] | T27: mV [kg/s] | U27: mV [kg/h]
L28: =B3 -> 39656.603 | M28: =2252*1000 -> 2252000 | N28: =L28/M28 -> 0.017609504 | O28: =N28*1000 -> 17.609504 | R28: =B6 -> 121632.31 | S28: 4190 | T28: =R28/S26/(G32-F32) -> 1.4514595 | U28: =T28*1000 -> 1451.4595
B29: Kondenzator-2 | L29: Q4 [W] | M29: dVapH [J/kg] | N29: mOP [kg/s] | O29: mOP [kg/h] | R29: Q7 [W] | S29: cpV [J//kg/K] | T29: mV [kg/s] | U29: mV [kg/h]
B30: Protiprúdny výmenník tepla | L30: =B5 -> 116242.44 | M30: =2252*1000 -> 2252000 | N30: =L30/M30 -> 0.051617424 | O30: =N30*1000 -> 51.617424 | R30: =B8 -> 121275.64 | S30: 4190 | T30: =R30/S26/(G38-F38) -> 1.4472033 | U30: =T30*1000 -> 1447.2033
B31: Q [W] | C31: k [W/m2/K] | D31: tH1 | E31: tH2 | F31: tS1 | G31: tS2 | H31: dtls | I31: A [m2] | J31: A [ft2] | L31: Q6 [W] | M31: dVapH [J/kg] | N31: mOP [kg/s] | O31: mOP [kg/h] | T31: SUMA | U31: =U26+U28+U30 -> 3371.892 | V31: kg/h
B32: =B6 -> 121632.31 | C32: =150*5.6873 -> 853.095 | D32: ='EB-VT'!C36 -> 45.124085 | E32: ='EB-VT'!C37 -> 25 | F32: 15 | G32: 35 | H32: =((D32-G32)-(E32-F32))/LN((D32-G32)/(E32-F32)) -> 10.061915 | I32: =B32/C32/H32 -> 14.170035 | J32: =10.7639104167*I32 -> 152.52498 | L32: =B7 -> 107161.77 | M32: =2252*1000 -> 2252000 | N32: =L32/M32 -> 0.047585158 | O32: =N32*1000 -> 47.585158 | V32: kg/rok
N33: SUMA | O33: =O26+O28+O30+O32 -> 125.94635 | P33: kg/h
P34: kg/rok
B35: Kondenzator-3 | S35: https://www.matche.com/equipcost/Exchanger.html
B36: Protiprúdny výmenník tepla | S36: Cena
B37: Q [W] | C37: k [W/m2/K] | D37: tH1 | E37: tH2 | F37: tS1 | G37: tS2 | H37: dtls | I37: A [m2] | J37: A [ft2] | R37: Zariadenie | S37: 2014 | T37: 2025
B38: =B8 -> 121275.64 | C38: =150*5.6873 -> 853.095 | D38: ='EB-VT'!C44 -> 45.043753 | E38: ='EB-VT'!C45 -> 25 | F38: 15 | G38: 35 | H38: =((D38-G38)-(E38-F38))/LN((D38-G38)/(E38-F38)) -> 10.021861 | I38: =B38/C38/H38 -> 14.18495 | J38: =10.7639104167*I38 -> 152.68553 | R38: Ohrevac-1 | S38: 6000 | T38: =$H$3/$H$5*S38 -> 8175.6639
R39: Ohrievac-2 | S39: 42400 | T39: =$H$3/$H$5*S39 -> 57774.692
B40: Cerpadlo | R40: Kondenzator-1 | S40: 22300 | T40: =$H$3/$H$5*S40 -> 30386.218
B41: V [m3/s] | C41: V [gal/min] | D41: Pv [W] | E41: Pp [W] | F41: head [ft] | G41: pa [psi] | H41: Type | I41: V[m3/h] | J41: P2-P1 [kPa] | K41: capacity factor | M41: Cena(2002) | N41: Cena(2025) | R41: Kondenzator-2 | S41: 48500 | T41: =$H$3/$H$5*S41 -> 66086.617
A42: P-1 | B42: =cerpadla!B20 -> 0.0006824286 | C42: =B42*15850.3 -> 10.816698 | D42: =cerpadla!J20 -> 26.149751 | E42: =cerpadla!L20 -> 37.356786 | F42: =cerpadla!G20* 3.28084 -> 16.4042 | G42: =(cerpadla!F20)/6.895/1000 -> 14.695431 | H42: odstredivé čerpadlo (centrifugal) | I42: =B42*3600 -> 2.456743 | J42: =(cerpadla!F20-cerpadla!E20)/1000 -> 0 | K42: =345*Ekonomika!B42 -> 0.23543787 | L42: =C42*G42 -> 158.95605 | M42: =750*1.8 -> 1350 | N42: =M42*$H$3/$H$2 -> 2678.8423 | R42: Kondenzator-3 | S42: 48500 | T42: =$H$3/$H$5*S42 -> 66086.617
A43: P-2 | B43: =cerpadla!B21 -> 8.5773602e-05 | C43: =B43*15850.3 -> 1.3595373 | D43: =cerpadla!J21 -> 5.2634277 | E43: =cerpadla!L21 -> 7.5191824 | F43: =cerpadla!G21* 3.28084 -> 3.28084 | G43: =(cerpadla!F21)/6.895/1000 -> 14.695431 | H43: odstredivé čerpadlo (centrifugal) | I43: =B43*3600 -> 0.30878497 | J43: =(cerpadla!F21-cerpadla!E21)/1000 -> 51.325 | K43: =345*Ekonomika!B43 -> 0.029591893 | L43: =C43*G43 -> 19.978988 | M43: =750*1.8 -> 1350 | N43: =M43*$H$3/$H$2 -> 2678.8423 | R43: Odparka-1 | S43: 416200 | T43: =$H$3/$H$5*S43 -> 567118.56
A44: P-3 | B44: =cerpadla!B22 -> 0.00013116224 | C44: =B44*15850.3 -> 2.0789609 | D44: =cerpadla!J22 -> 14.340784 | E44: =cerpadla!L22 -> 20.486835 | F44: =cerpadla!G22* 3.28084 -> 3.28084 | G44: =(cerpadla!F22)/6.895/1000 -> 14.695431 | H44: odstredivé čerpadlo (centrifugal) | I44: =B44*3600 -> 0.47218407 | J44: =(cerpadla!F22-cerpadla!E22)/1000 -> 98.875 | K44: =345*Ekonomika!B44 -> 0.045250974 | L44: =C44*G44 -> 30.551227 | M44: =750*1.8 -> 1350 | N44: =M44*$H$3/$H$2 -> 2678.8423 | R44: Odparka-2 | S44: 384900 | T44: =$H$3/$H$5*S44 -> 524468.84
A45: P-4 | B45: =cerpadla!B23 -> 0.00061889488 | C45: =B45*15850.3 -> 9.8096694 | D45: =cerpadla!J23 -> 102.33014 | E45: =cerpadla!L23 -> 146.18592 | F45: =cerpadla!G23* 3.28084 -> 16.4042 | G45: =(cerpadla!F23)/6.895/1000 -> 14.695431 | H45: Gear-lobe | I45: =B45*3600 -> 2.2280216 | J45: =(cerpadla!F23-cerpadla!E23)/1000 -> 98.875 | K45: =345*Ekonomika!B45 -> 0.21351873 | L45: =C45*G45 -> 144.15733 | M45: =2974+780 -> 3754 | N45: =M45*$H$3/$H$2 -> 7449.1658 | T45: =SUM(T37:T44) -> 1322122.2
A46: P-5 | B46: =cerpadla!B24 -> 0.00044848891 | C46: =B46*15850.3 -> 7.1086838 | D46: =cerpadla!J24 -> 15.251298 | E46: =cerpadla!L24 -> 21.787568 | F46: =cerpadla!G24* 3.28084 -> 1.64042 | G46: =(cerpadla!F24)/6.895/1000 -> 14.695431 | H46: odstredivé čerpadlo (centrifugal) | I46: =B46*3600 -> 1.6145601 | J46: =(cerpadla!F24-cerpadla!E24)/1000 -> 27.825 | K46: =345*Ekonomika!B46 -> 0.15472867 | L46: =C46*G46 -> 104.46518 | M46: =750*1.8 -> 1350 | N46: =M46*$H$3/$H$2 -> 2678.8423
...

Sheet Ceny
A1: Investicne naklady | F1: Prevadzkove naklady | K1: dni | L1: 330
A2: Zariadenie | C2: cena | F2: Spotreba ohrevnej pary | K2: h | L2: =L1*24 -> 7920
A3: Cerpadlo-1 | B3: P-1 | C3: =Ekonomika!N42 -> 2678.8423 | F3: mOP [kg/h] | G3: mOP [kg/rok]
A4: Cerpadlo-2 | B4: P-2 | C4: =Ekonomika!N43 -> 2678.8423 | F4: =Ekonomika!O33 -> 125.94635 | G4: =$L$2*F4 -> 997495.1
A5: Cerpadlo-3 | B5: P-3 | C5: =Ekonomika!N44 -> 2678.8423 | F5: Spotreba chladiacej vody
A6: Cerpadlo-4 | B6: P-4 | C6: =Ekonomika!N45 -> 7449.1658 | F6: mV [kg/h] | G6: mV [kg/rok]
A7: Cerpadlo-5 | B7: P-5 | C7: =Ekonomika!N46 -> 2678.8423 | F7: =Ekonomika!U31 -> 3371.892 | G7: =$L$2*F7 -> 26705384
A8: Cerpadlo-6 | B8: P-6 | C8: =Ekonomika!N47 -> 2678.8423 | F8: Spotreba IL
A9: Ohrevac-1 | B9: H-1 | C9: =Ekonomika!T38 -> 8175.6639 | F9: nIL [kmol/h] | G9: mIL [kg/h] | H9: cena za kg
A10: Ohrievac-2 | B10: H-2 | C10: =Ekonomika!T39 -> 57774.692 | F10: ='EB-VT'!E28*'EB-VT'!H28 -> 11.899981 | G10: =F10*236.29 -> 2811.8466 | H10: 15
A11: Kondenzator-1 | B11: K-1 | C11: =Ekonomika!T40 -> 30386.218 | H11: =G10*H10 -> 42177.699
A12: Kondenzator-2 | B12: K-2 | C12: =Ekonomika!T41 -> 66086.617
A13: Kondenzator-3 | B13: K-3 | C13: =Ekonomika!T42 -> 66086.617 | G13: cena za kg | H13: kmol/h | I13: kg/h
A14: Odparka-1 | B14: D-1 | C14: =Ekonomika!T43 -> 567118.56 | F14: MTBE | G14: 0.74 | H14: ='EB-VT'!E45*'EB-VT'!F45 -> 13.455976 | I14: =H14*88.15 -> 1186.1443
A15: Odparka-2 | B15: D-2 | C15: =Ekonomika!T44 -> 524468.84 | I15: zisk
A16: Extrakcna kolona | C16: =Ekonomika!R6 -> 72627.148 | I16: =I14*G14 -> 877.74676
B17: TOTAL | C17: =SUM(C3:C16) -> 1413567.7
