Workbook

Sheet Kolona
AE1: Vstupne prudy
B2: xi | E2: n [kmol/h] | G2: '=xe/xr | AF2: n | AG2: xA | AH2: xB | AI2: xC
B3: A | C3: B | D3: C | E3: A+B+C | G3: kA | H3: kB | I3: kC | L3: 1 | M3: 2 | N3: 3 | O3: 4 | P3: 5 | Q3: psA | S3: inverz | Z3: xA | AD3: F | AE3: MeOH z Extr | AF3: =AJ14 -> 5.4997212 | AG3: =AJ15 -> 0.18381571 | AH3: =AJ16 -> 0.81618429 | AI3: =AJ17 -> 0
A4: F | B4: =AA26 -> 0.47577272 | C4: =AB26 -> 0.52422728 | D4: =AC26 -> 0 | E4: =AA30 -> 30.499721 | G4: - | H4: - | I4: - | K4: A(zlozka A) | L4: =E$10*$G$5+E$5 -> 16.977068 | M4: =-$E$11*$G$6 -> -0.15270495 | N4: 0 | O4: 0 | P4: 0 | Q4: =$B$4*$E$4 -> 14.510935 | T4: {=MINVERSE(L4:P8)} -> 0.059507755 | U4: 0.0006516535 | V4: 1.9694901e-06 | W4: 4.6148997e-09 | X4: 1.0377422e-11 | Z4: {=MMULT(T4:X8,Q4:Q8)} -> 0.86351317 | AE4: Surovina | AF4: 25 | AG4: 0.54 | AH4: 0.46 | AI4: 0
A5: R1 | B5: =S31 -> 0.86351317 | C5: =T31 -> 0.13521519 | D5: =U31 -> 0.0012716362 | E5: =AA31 -> 15.755573 | G5: =B10/B5 -> 0.041914007 | H5: =C10/C5 -> 4.1096788 | I5: =D10/D5 -> 320.93746 | L5: =-$E$5 -> -15.755573 | M5: =$E$6+$E$11*$G$6 -> 13.986535 | N5: =-$G$7*$E$12 -> -0.041051104 | O5: 0 | P5: 0 | Q5: 0 | T5: 0.067235372 | U5: 0.07244798 | V5: 0.00021895927 | W5: 5.1306432e-07 | X5: 1.1537163e-09 | Z5: 0.97564812 | AD5: S | AE5: W z Raffinatu | AF5: =AK14 -> 0.025278913 | AG5: =AK15 -> 0.7496859 | AH5: =AK16 -> 0.00031410576 | AI5: =AK17 -> 0.25
A6: R2 | B6: =S32 -> 0.97564812 | C6: =T32 -> 0.02378934 | D6: =U32 -> 0.00056253806 | E6: =AA32 -> 13.83383 | G6: =B11/B6 -> 0.010605454 | H6: =C11/C6 -> 6.8198273 | I6: =D11/D6 -> 1470.858 | L6: 0 | M6: =-$E$6 -> -13.83383 | N6: =$E$7+$E$12*$G$7 -> 13.614558 | O6: =-$E$13*$G$8 -> -0.031719159 | P6: 0 | Q6: 0 | T6: 0.068478222 | U6: 0.073787186 | V6: 0.073845789 | W6: 0.0001730351 | X6: 3.8910017e-07 | Z6: 0.99368305 | AE6: Cista IL | AF6: 0 | AG6: 0 | AH6: 0 | AI6: 1
A7: R3 | B7: =S33 -> 0.99368305 | C7: =T33 -> 0.0058360033 | D7: =U33 -> 0.00048094862 | E7: =AA33 -> 13.573506 | G7: =B12/B7 -> 0.0032901482 | H7: =C12/C7 -> 7.3437685 | I7: =D12/D7 -> 1983.3145 | L7: 0 | M7: 0 | N7: =-$E$7 -> -13.573506 | O7: =$E$8+$E$13*$G$8 -> 13.567149 | P7: =-$E$14*$G$9 -> -0.03046731 | Q7: 0 | T7: 0.068664353 | U7: 0.073987747 | V7: 0.07404651 | W7: 0.074046687 | X7: 0.00016650714 | Z7: 0.99638714 | AE7: W z Extraktu | AF7: =AL14 -> 12.136389 | AG7: =AL15 -> 2.3429527e-07 | AH7: =AL16 -> 0.01999977 | AI7: =AL17 -> 0.98
A8: R4 | B8: =S34 -> 0.99638714 | C8: =T34 -> 0.0031436435 | D8: =U34 -> 0.0004692192 | E8: =AA34 -> 13.53543 | G8: =B13/B8 -> 0.002596387 | H8: =C13/C8 -> 7.4172709 | I8: =D13/D8 -> 2075.9929 | L8: 0 | M8: 0 | N8: 0 | O8: =-$E$8 -> -13.53543 | P8: =$E$9+$E$14*$G$9 -> 13.548989 | Q8: =$E$15*$B$15 -> 0.018954088 | T8: 0.068595638 | U8: 0.073913704 | V8: 0.073972408 | W8: 0.073972585 | X8: 0.073972585 | Z8: 0.99678893
A9: R5 | B9: =S35 -> 0.99678893 | C9: =T35 -> 0.0027435803 | D9: =U35 -> 0.00046748711 | E9: =AA35 -> 13.518522 | G9: =B14/B9 -> 0.0025017135 | H9: =C14/C9 -> 7.428099 | I9: =D14/D9 -> 2090.1683 | AD9: vysledne | AE9: F | AF9: =AF3+AF4 -> 30.499721 | AG9: =(AG4*$AF$4+$AF$3*AG3)/$AF$9 -> 0.47577272 | AH9: =(AH4*$AF$4+$AF$3*AH3)/$AF$9 -> 0.52422728 | AI9: =(AI4*$AF$4+$AF$3*AI3)/$AF$9 -> 0
A10: E1 | B10: =W31 -> 0.036193297 | C10: =X31 -> 0.55569101 | D10: =Y31 -> 0.40811569 | E10: =AB31 -> 29.142868 | L10: 1 | M10: 2 | N10: 3 | O10: 4 | P10: 5 | Q10: psB | S10: inverz | Z10: xB | AE10: S | AF10: =AF6+AF7+AF5 -> 12.161668 | AG10: =(AG6*$AF$6+$AF$7*AG7+AF5*AG5)/$AF$10 -> 0.0015585105 | AH10: =(AH6*$AF$6+$AF$7*AH7+AF5*AH5)/$AF$10 -> 0.019958852 | AI10: =(AI6*$AF$6+$AF$7*AI7+AF5*AI5)/$AF$10 -> 0.97848264
A11: E2 | B11: =W32 -> 0.010347191 | C11: =X32 -> 0.16223919 | D11: =Y32 -> 0.82741362 | E11: =AB32 -> 14.39872 | K11: A(zlozka B) | L11: =E$10*$H$5+E$5 -> 135.5234 | M11: =-$E$11*$H$6 -> -98.196782 | N11: 0 | O11: 0 | P11: 0 | Q11: =$C$4*$E$4 -> 15.988786 | T11: {=MINVERSE(L11:P15)} -> 0.0083490525 | U11: 0.008345744 | V11: 0.0083222586 | W11: 0.0081637203 | X11: 0.007102371 | Z11: {=MMULT(T11:X15,Q11:Q15)} -> 0.13521519
A12: E3 | B12: =W33 -> 0.0032693645 | C12: =X33 -> 0.042858257 | D12: =Y33 -> 0.95387238 | E12: =AB33 -> 12.476977 | L12: =-$E$5 -> -15.755573 | M12: =$E$6+$E$11*$H$6 -> 112.03061 | N12: =-$H$7*$E$12 -> -91.62803 | O12: 0 | P12: 0 | Q12: 0 | T12: 0.0013390661 | U12: 0.011518133 | V12: 0.01148572 | W12: 0.011266918 | X12: 0.0098021283 | Z12: 0.02378934 | AF12: Udaje vstupne
A13: E4 | B13: =W34 -> 0.0025870066 | C13: =X34 -> 0.023317255 | D13: =Y34 -> 0.97409574 | E13: =AB34 -> 12.216653 | L13: 0 | M13: =-$E$6 -> -13.83383 | N13: =$E$7+$E$12*$H$7 -> 105.20154 | O13: =-$E$13*$H$8 -> -90.614225 | P13: 0 | Q13: 0 | T13: 0.0002016008 | U13: 0.0017340928 | V13: 0.012612192 | W13: 0.012371931 | X13: 0.010763481 | Z13: 0.0058360033 | AF13: Ventil-exit | AG13: Raf-exit | AH13: Ext-exit | AJ13: Ventil-exit | AK13: Raf-exit | AL13: Ext-exit | AO13: delta
A14: E5 | B14: =W35 -> 0.0024936804 | C14: =X35 -> 0.020379587 | D14: =Y35 -> 0.97712673 | E14: =AB35 -> 12.178576 | L14: 0 | M14: 0 | N14: =-$E$7 -> -13.573506 | O14: =$E$8+$E$13*$H$8 -> 104.14965 | P14: =-$E$14*$H$9 -> -90.463672 | Q14: 0 | T14: 2.9623395e-05 | U14: 0.00025480909 | V14: 0.0018532464 | W14: 0.012643506 | X14: 0.010999749 | Z14: 0.0031436435 | AE14: n | AF14: =SF!Y2 -> 5.4997512 | AG14: ='Odparka-Rafinat'!C31 -> 0.025278938 | AH14: ='Odparka-Extrakt'!C32 -> 12.136389 | AJ14: 5.4997212 | AK14: 0.025278913 | AL14: 12.136389 | AO14: =AF14-AJ14 -> 3.0017586e-05 | AP14: =AG14-AK14 -> 2.5270072e-08 | AQ14: =AH14-AL14 -> -6.0424922e-08 | AR14: =AI14-AM14 -> 0
A15: S | B15: =W36 -> 0.0015585105 | C15: =X36 -> 0.019958852 | D15: =Y36 -> 0.97848264 | E15: =AB36 -> 12.161668 | L15: 0 | M15: 0 | N15: 0 | O15: =-$E$8 -> -13.53543 | P15: =$E$9+$E$14*$H$9 -> 103.98219 | Q15: =$E$15*$C$15 -> 0.24273294 | T15: 3.8560967e-06 | U15: 3.3168665e-05 | V15: 0.00024123829 | W15: 0.0016458134 | X15: 0.011048876 | Z15: 0.0027435803 | AE15: xA | AF15: =SF!Y3 -> 0.18381489 | AG15: ='Odparka-Rafinat'!C32 -> 0.7496859 | AH15: ='Odparka-Extrakt'!C33 -> 2.3429527e-07 | AJ15: 0.18381571 | AK15: 0.7496859 | AL15: 2.3429527e-07 | AO15: =AF15-AJ15 -> -8.1991234e-07 | AP15: =AG15-AK15 -> -8.1784912e-11 | AQ15: =AH15-AL15 -> 0 | AR15: =AI15-AM15 -> 0
AE16: xB | AF16: =SF!Y4 -> 0.81618511 | AG16: ='Odparka-Rafinat'!C33 -> 0.00031410579 | AH16: ='Odparka-Extrakt'!C34 -> 0.01999977 | AJ16: 0.81618429 | AK16: 0.00031410576 | AL16: 0.01999977 | AO16: =AF16-AJ16 -> 8.1991234e-07 | AP16: =AG16-AK16 -> 3.4221218e-11 | AQ16: =AH16-AL16 -> 0 | AR16: =AI16-AM16 -> 0
L17: 1 | M17: 2 | N17: 3 | O17: 4 | P17: 5 | Q17: psC | S17: inverz | Z17: xC | AE17: xC | AF17: =SF!Y5 -> 0 | AG17: ='Odparka-Rafinat'!C34 -> 0.25 | AH17: ='Odparka-Extrakt'!C35 -> 0.98 | AJ17: 0 | AK17: 0.25 | AL17: 0.98 | AO17: =AF17-AJ17 -> 0 | AP17: =AG17-AK17 -> 0 | AQ17: =AH17-AL17 -> 0 | AR17: =AI17-AM17 -> 0
A18: A | B18: MTBE | K18: A(zlozka C) | L18: =E$10*$I$5+E$5 -> 9368.7934 | M18: =-$E$11*$I$6 -> -21178.473 | N18: 0 | O18: 0 | P18: 0 | Q18: =$D$4*$E$4 -> 0 | T18: {=MINVERSE(L18:P22)} -> 0.00010691713 | U18: 0.00010691713 | V18: 0.00010691713 | W18: 0.0001069171 | X18: 0.00010686035 | Z18: {=MMULT(T18:X22,Q18:Q22)} -> 0.0012716362
A19: B | B19: Methanol | L19: =-$E$5 -> -15.755573 | M19: =$E$6+$E$11*$I$6 -> 21192.307 | N19: =-$I$7*$E$12 -> -24745.769 | O19: 0 | P19: 0 | Q19: 0 | T19: 7.9540236e-08 | U19: 4.7297298e-05 | V19: 4.7297298e-05 | W19: 4.7297285e-05 | X19: 4.727218e-05 | Z19: 0.00056253806
A20: C | B20: [BMIM][HSO4] | L20: 0 | M20: =-$E$6 -> -13.83383 | N20: =$E$7+$E$12*$I$7 -> 24759.343 | O20: =-$E$13*$I$8 -> -25361.685 | P20: 0 | Q20: 0 | T20: 4.446603e-11 | U20: 2.6440996e-08 | V20: 4.0437389e-05 | W20: 4.0437378e-05 | X20: 4.0415914e-05 | Z20: 0.00048094862
L21: 0 | M21: 0 | N21: =-$E$7 -> -13.573506 | O21: =$E$8+$E$13*$I$8 -> 25375.221 | P21: =-$E$14*$I$9 -> -25455.274 | Q21: 0 | T21: 2.3798094e-14 | U21: 1.4151147e-11 | V21: 2.1641977e-08 | W21: 3.9451187e-05 | X21: 3.9430247e-05 | Z21: 0.0004692192
L22: 0 | M22: 0 | N22: 0 | O22: =-$E$8 -> -13.53543 | P22: =$E$9+$E$14*$I$9 -> 25468.793 | Q22: =$E$15*$D$15 -> 11.899981 | T22: 1.2647534e-17 | U22: 7.5206491e-15 | V22: 1.1501662e-11 | W22: 2.0966395e-08 | X22: 3.9284693e-05 | Z22: 0.00046748711
Z25: n[kmol/h] | AA25: xA | AB25: xB | AC25: xC | AE25: ns | AF25: ns/nf | AG25: Ya(straty | AH25: Yb | AI25: Yc(straty)
L26: Raf | Y26: F | Z26: =AF9 -> 30.499721 | AA26: =AG9 -> 0.47577272 | AB26: =AH9 -> 0.52422728 | AC26: =AI9 -> 0 | AE26: =Z27 -> 12.161668 | AF26: =AE26/Z26 -> 0.39874687 | AG26: =AB31*W31/Z26/AA26 -> 0.072688387 | AH26: =(X31*AB31-Z27*AB27)/Z26/AB26 -> 0.9976803 | AI26: =AA35*U35/AB36/AC27 -> 0.00053107097
L27: A | M27: B | N27: C | O27: ∑xRi | Y27: S | Z27: =AF10 -> 12.161668 | AA27: =AG10 -> 0.0015585105 | AB27: =AH10 -> 0.019958852 | AC27: =AI10 -> 0.97848264
L28: =Z4 -> 0.86351317 | M28: =Z11 -> 0.13521519 | N28: =Z18 -> 0.0012716362 | O28: =SUM(L28:N28) -> 1
L29: =Z5 -> 0.97564812 | M29: =Z12 -> 0.02378934 | N29: =Z19 -> 0.00056253806 | O29: =SUM(L29:N29) -> 1 | AA29: nR [kmol/h][mol.h-1] | AB29: nE [kmol/h]
L30: =Z6 -> 0.99368305 | M30: =Z13 -> 0.0058360033 | N30: =Z20 -> 0.00048094862 | O30: =SUM(L30:N30) -> 1 | R30: Kontakt | S30: xRA | T30: xRB | U30: xRC | V30: ∑xRi | W30: xEA | X30: xEB | Y30: xEC | Z30: ∑xEi | AA30: =Z26 -> 30.499721 | AC30: kA | AD30: kB | AE30: kC | AG30: Ziadane
L31: =Z7 -> 0.99638714 | M31: =Z14 -> 0.0031436435 | N31: =Z21 -> 0.0004692192 | O31: =SUM(L31:N31) -> 1 | R31: 1 | S31: =C41 -> 0.86351317 | T31: =D41 -> 0.13521519 | U31: =E41 -> 0.0012716362 | V31: =SUM(S31:U31) -> 1 | W31: =G41 -> 0.036193297 | X31: =H41 -> 0.55569101 | Y31: =I41 -> 0.40811569 | Z31: =SUM(W31:Y31) -> 1 | AA31: =(AB33*(W32-W33)+AA32*(S32-W32))/(S31-W32) -> 15.755573 | AB31: =AA30+AB36-AA35 -> 29.142868 | AC31: =W31/S31 -> 0.041914007 | AD31: =X31/T31 -> 4.1096788 | AE31: =Y31/U31 -> 320.93746 | AG31: xEB1 | AH31: 0.55567184
L32: =Z8 -> 0.99678893 | M32: =Z15 -> 0.0027435803 | N32: =Z22 -> 0.00046748711 | O32: =SUM(L32:N32) -> 1 | R32: 2 | S32: =C42 -> 0.97564812 | T32: =D42 -> 0.02378934 | U32: =E42 -> 0.00056253806 | V32: =SUM(S32:U32) -> 1 | W32: =G42 -> 0.010347191 | X32: =H42 -> 0.16223919 | Y32: =I42 -> 0.82741362 | Z32: =SUM(W32:Y32) -> 1 | AA32: =(AB34*(W33-W34)+AA33*(S33-W33))/(S32-W33) -> 13.83383 | AB32: =AA31+AB33-AA32 -> 14.39872 | AC32: =W32/S32 -> 0.010605454 | AD32: =X32/T32 -> 6.8198273 | AE32: =Y32/U32 -> 1470.858 | AG32: xRB5 | AH32: 0.00018667141 | AI32: 0.13520594
R33: 3 | S33: =C43 -> 0.99368305 | T33: =D43 -> 0.0058360033 | U33: =E43 -> 0.00048094862 | V33: =SUM(S33:U33) -> 1 | W33: =G43 -> 0.0032693645 | X33: =H43 -> 0.042858257 | Y33: =I43 -> 0.95387238 | Z33: =SUM(W33:Y33) -> 1 | AA33: =(AB35*(W34-W35)+AA34*(S34-W34))/(S33-W34) -> 13.573506 | AB33: =AA32+AB34-AA33 -> 12.476977 | AC33: =W33/S33 -> 0.0032901482 | AD33: =X33/T33 -> 7.3437685 | AE33: =Y33/U33 -> 1983.3145 | AG33: Vypocitane
R34: 4 | S34: =C44 -> 0.99638714 | T34: =D44 -> 0.0031436435 | U34: =E44 -> 0.0004692192 | V34: =SUM(S34:U34) -> 1 | W34: =G44 -> 0.0025870066 | X34: =H44 -> 0.023317255 | Y34: =I44 -> 0.97409574 | Z34: =SUM(W34:Y34) -> 1 | AA34: =(AB36*(W35-W36)+AA35*(S35-W35))/(S34-W35) -> 13.53543 | AB34: =AA33+AB35-AA34 -> 12.216653 | AC34: =W34/S34 -> 0.002596387 | AD34: =X34/T34 -> 7.4172709 | AE34: =Y34/U34 -> 2075.9929 | AG34: xEB1 | AH34: =(Z26*AB26+Z27*AB27-AA35*T35)/AB31 -> 0.55569101
C35: τ12 | D35: τ21 | E35: τ13 | F35: τ31 | G35: τ23 | H35: τ32 | R35: 5 | S35: =C45 -> 0.99678893 | T35: =D45 -> 0.0027435803 | U35: =E45 -> 0.00046748711 | V35: =SUM(S35:U35) -> 1 | W35: =G45 -> 0.0024936804 | X35: =H45 -> 0.020379587 | Y35: =I45 -> 0.97712673 | Z35: =SUM(W35:Y35) -> 1 | AA35: =(AA30*(AA26-W31)+AB36*(AA27-W31))/(S35-W31) -> 13.518522 | AB35: =AA34+AB36-AA35 -> 12.178576 | AC35: =W35/S35 -> 0.0025017135 | AD35: =X35/T35 -> 7.428099 | AE35: =Y35/U35 -> 2090.1683 | AG35: xRB5 | AH35: =(Z26*AB26+Z27*AB27-AB31*X31)/AA35 -> 0.0027435803
C36: 2.10718 | D36: 2.8350923 | E36: 7.2849444 | F36: 6.1290709 | G36: 4.0246507 | H36: 0.21292208 | W36: =AA27 -> 0.0015585105 | X36: =AB27 -> 0.019958852 | Y36: =AC27 -> 0.97848264 | AB36: =Z27 -> 12.161668
C37: G12 | D37: G21 | E37: G13 | F37: G31 | G37: G23 | H37: G32 | AG37: xEBreg-xEB | AH37: xRBreg-xRB | AI37: sum
C38: 0.43047242 | D38: 0.32173183 | E38: 0.054259468 | F38: 0.086153183 | G38: 0.19991554 | H38: 0.91835722 | AG38: =(AH34-AH31)^2 -> 3.6768582e-10 | AH38: =(AH32-AH35)^2 -> 6.5377833e-06 | AI38: =AG38+AH38 -> 6.538151e-06
C40: x1.1 | D40: x2.1 | E40: x3.1 | G40: x1.2 | H40: x2.2 | I40: x3.2 | L40: φ1.1 | M40: φ2.1 | N40: φ3.1 | O40: θ1.1 | P40: θ2.1 | Q40: θ3.1 | R40: lnγ1.1 | S40: lnγ2.1 | T40: lnγ3.1 | U40: γ1.1 | V40: γ2.1 | W40: γ3.1 | X40: γ1.1/γ1.2 | Y40: γ2.1/γ2.2 | Z40: γ3.1/γ3.2 | AF40: potrebne vystupy pre odparku
C41: =1-D41-E41 -> 0.86351317 | D41: 0.13521519 | E41: 0.0012716362 | G41: 0.036193297 | H41: 0.55569101 | I41: =1-G41-H41 -> 0.40811569 | L41: =$C41+$D$38*$D41+$F$38*$E41 -> 0.90712576 | M41: =$C$38*$C41+$D41+$H$38*$E41 -> 0.50810162 | N41: =$E$38*$C41+$G$38*$D41+$E41 -> 0.07515702 | O41: =$D41*$D$36*$D$38+$E41*$F$36*$F$38 -> 0.12400658 | P41: =$C41*$C$36*$C$38+$E41*$H$36*$H$38 -> 0.78352668 | Q41: =$C41*$E$36*$E$38+$D41*$G$36*$G$38 -> 0.4501199 | R41: =(O41/L41)-(C41*O41/L41^2)+(D41*$C$38/M41)*($C$36-P41/M41)+(E41*$E$38/N41)*($E$36-Q41/N41) -> 0.072499518 | S41: =(P41/M41)-(D41*P41/M41^2)+(C41*$D$38/L41)*($D$36-O41/L41)+(E41*$G$38/N41)*($G$36-Q41/N41) -> 1.9514686 | T41: =(Q41/N41)-(E41*Q41/N41^2)+(C41*$F$38/L41)*($F$36-O41/L41)+(D41*$H$38/M41)*($H$36-P41/M41) -> 6.0543355 | U41: =EXP(R41) -> 1.0751923 | V41: =EXP(S41) -> 7.0390172 | W41: =EXP(T41) -> 425.95578 | X41: =U41/U47 -> 0.041914007 | Y41: =V41/V47 -> 4.1096788 | Z41: =W41/W47 -> 320.93746 | AE41: n | AF41: =AB31 -> 29.142868 | AG41: =AA35 -> 13.518522
C42: =1-D42-E42 -> 0.97564812 | D42: 0.02378934 | E42: 0.00056253806 | G42: 0.010347191 | H42: 0.16223919 | I42: =1-G42-H42 -> 0.82741362 | L42: =$C42+$D$38*$D42+$F$38*$E42 -> 0.98335037 | M42: =$C$38*$C42+$D42+$H$38*$E42 -> 0.44429556 | N42: =$E$38*$C42+$G$38*$D42+$E42 -> 0.058256545 | O42: =$D42*$D$36*$D$38+$E42*$F$36*$F$38 -> 0.021996237 | P42: =$C42*$C$36*$C$38+$E42*$H$36*$H$38 -> 0.88510372 | Q42: =$C42*$E$36*$E$38+$D42*$G$36*$G$38 -> 0.40479214 | R42: =(O42/L42)-(C42*O42/L42^2)+(D42*$C$38/M42)*($C$36-P42/M42)+(E42*$E$38/N42)*($E$36-Q42/N42) -> 0.0030028478 | S42: =(P42/M42)-(D42*P42/M42^2)+(C42*$D$38/L42)*($D$36-O42/L42)+(E42*$G$38/N42)*($G$36-Q42/N42) -> 2.7776935 | T42: =(Q42/N42)-(E42*Q42/N42^2)+(C42*$F$38/L42)*($F$36-O42/L42)+(D42*$H$38/M42)*($H$36-P42/M42) -> 7.3158468 | U42: =EXP(R42) -> 1.0030074 | V42: =EXP(S42) -> 16.081886 | W42: =EXP(T42) -> 1503.9447 | X42: =U42/U48 -> 0.010605454 | Y42: =V42/V48 -> 6.8198273 | Z42: =W42/W48 -> 1470.858 | AE42: xA | AF42: =W31 -> 0.036193297 | AG42: =S35 -> 0.99678893
C43: =1-D43-E43 -> 0.99368305 | D43: 0.0058360033 | E43: 0.00048094862 | G43: 0.0032693645 | H43: 0.042858257 | I43: =1-G43-H43 -> 0.95387238 | L43: =$C43+$D$38*$D43+$F$38*$E43 -> 0.99560211 | M43: =$C$38*$C43+$D43+$H$38*$E43 -> 0.43403084 | N43: =$E$38*$C43+$G$38*$D43+$E43 -> 0.05556437 | O43: =$D43*$D$36*$D$38+$E43*$F$36*$F$38 -> 0.0055772083 | P43: =$C43*$C$36*$C$38+$E43*$H$36*$H$38 -> 0.90144694 | Q43: =$C43*$E$36*$E$38+$D43*$G$36*$G$38 -> 0.39747585 | R43: =(O43/L43)-(C43*O43/L43^2)+(D43*$C$38/M43)*($C$36-P43/M43)+(E43*$E$38/N43)*($E$36-Q43/N43) -> 0.00024771876 | S43: =(P43/M43)-(D43*P43/M43^2)+(C43*$D$38/L43)*($D$36-O43/L43)+(E43*$G$38/N43)*($G$36-Q43/N43) -> 2.9521611 | T43: =(Q43/N43)-(E43*Q43/N43^2)+(C43*$F$38/L43)*($F$36-O43/L43)+(D43*$H$38/M43)*($H$36-P43/M43) -> 7.5950348 | U43: =EXP(R43) -> 1.0002477 | V43: =EXP(S43) -> 19.147288 | W43: =EXP(T43) -> 1988.299 | X43: =U43/U49 -> 0.0032901482 | Y43: =V43/V49 -> 7.3437685 | Z43: =W43/W49 -> 1983.3145 | AE43: xB | AF43: =X31 -> 0.55569101 | AG43: =T35 -> 0.0027435803
...

Sheet SF
A1: A | B1: MTBE | E1: NRTL parameters: | J1: R | L1: Antoine equation parameters (Pa) | V1: pre odparku | Y1: pre Extraktor
A2: B | B2: Metanol | E2: alphaAB | F2: 0.4 | G2: gAB | H2: 5.5737 | J2: =8.314/1000 -> 0.008314 | M2: A | N2: B | O2: C | R2: MACRO | U2: n | V2: =C18 -> 23.643117 | Y2: =D18 -> 5.4997512
A3: C | B3: [BMIM][HSO4] | G3: gBA | H3: 7.4991 | J3: P - ventil | K3: kPa | L3: A | M3: 20.84054 | N3: -2624.525 | O3: -46.15171 | R3: CTRL+Q | U3: xa | V3: =C19 -> 0.001854252 | Y3: =D19 -> 0.18381489
G4: gAC | H4: 19.2694 | J4: 50 | L4: B | M4: 23.5347 | N4: -3661.468 | O4: -32.77001 | U4: xb | V4: =C21 -> 0.4950961 | Y4: =D21 -> 0.81618511
G5: gCA | H5: 16.212 | J5: P - pred | K5: kPa | L5: C | M5: 0 | N5: 0 | O5: 0 | U5: xc | V5: =C20 -> 0.50304965 | Y5: =D20 -> 0
G6: gBC | H6: 10.6456 | J6: 101.325
G7: gCB | H7: 0.5632
A9: t | B9: T | C9: xA | D9: xB | E9: xC | F9: PA0 | G9: PB0 | H9: PC0 | I9: yA | J9: yB | K9: yC | L9: SUMy
A10: =B10-273.15 -> 45.113903 | B10: 318.2639 | C10: =C19 -> 0.001854252 | D10: =C21 -> 0.4950961 | E10: =C20 -> 0.50304965 | F10: =EXP(M3+N3/(B10+O3))/1000 -> 72.804231 | G10: =EXP(M4+N4/(B10+O4))/1000 -> 44.786817 | H10: 0 | I10: =(C10*F10*S13)/J4 -> 0.18381485 | J10: =(D10*G10*T13)/J4 -> 0.81618515 | K10: 0 | L10: =SUM(I10:K10) -> 1
A12: τAB | B12: τBA | C12: τAC | D12: τCA | E12: τBC | F12: τCB | G12: GAB | H12: GBA | I12: GAC | J12: GCA | K12: GBC | L12: GCB | M12: θ1 | N12: θ2 | O12: θ3 | P12: φ1 | Q12: φ2 | R12: φ3 | S12: γA | T12: γB | U12: γC
A13: =H2/(J2*B10) -> 2.1064259 | B13: =H3/(J2*B10) -> 2.8340776 | C13: =H4/(J2*B10) -> 7.2823372 | D13: =H5/(J2*B10) -> 6.1268774 | E13: =H6/(J2*B10) -> 4.0232103 | F13: =H7/(J2*B10) -> 0.21284588 | G13: =EXP(-F2*A13) -> 0.4306023 | H13: =EXP(-F2*B13) -> 0.32186243 | I13: =EXP(-F2*C13) -> 0.054316084 | J13: =EXP(-F2*D13) -> 0.086228808 | K13: =EXP(-F2*E13) -> 0.20003076 | L13: =EXP(-F2*F13) -> 0.91838522 | M13: =D10*B13*H13+E10*D13*J13 -> 0.71738614 | N13: =C10*A13*G13+E10*F13*L13 -> 0.10001525 | O13: =C10*C13*I13+D10*E13*K13 -> 0.39916986 | P13: =C10+H13*D10+J13*E10 -> 0.20458446 | Q13: =G13*C10+D10+L13*E10 -> 0.9578879 | R13: =I13*C10+K13*D10+E10 -> 0.60218481 | S13: =EXP(M13/P13-(C10*M13)/P13^2+D10*G13/Q13*(A13-N13/Q13)+E10*I13/R13*(C13-O13/R13)) -> 68.08089 | T13: =EXP(N13/Q13-D10*N13/Q13^2+C10*H13/P13*(B13-M13/P13)+E10*K13/R13*(E13-O13/R13)) -> 1.8404287 | U13: =EXP(O13/R13-E10*O13/R13^2+C10*J13/P13*(D13-M13/P13)+D10*L13/Q13*(F13-N13/Q13)) -> 1.1766182
B15: VSTUP | C15: L | D15: G | I15: Metanol | S15: Stred. T | T15: vypA [kJ/kmol]
A16: t | B16: 68 | C16: =A10 -> 45.113903 | D16: =A10 -> 45.113903 | I16: A [kJ/mol] | J16: 45.3 | S16: =(B17+C17)/2 -> 329.70695 | T16: =J22*1000*EXP(-J23*D17/J24)*(1-D17/J24)^J23 -> 28578.353
A17: T | B17: =B16+273.15 -> 341.15 | C17: =C16+273.15 -> 318.2639 | D17: =D16+273.15 -> 318.2639 | I17: alpha | J17: -0.31 | S17: cpA [kJ/kmol/K] | T17: vypB
A18: n[kmol] | B18: =Kolona!AF47 -> 29.142868 | C18: =(B18*B20)/C20 -> 23.643117 | D18: =B18-C18 -> 5.4997512 | F18: odchylka | I18: beta | J18: 0.4241 | S18: 187.5 | T18: =J16*1000*EXP(-J17*D17/J19)*(1-D17/J19) -> 20819.158
A19: xA | B19: =Kolona!AF48 -> 0.036193297 | C19: 0.001854252 | D19: =(B18*B19-C18*C19)/D18 -> 0.18381489 | E19: =I10 -> 0.18381485 | F19: =(D19-E19)^2 -> 2.1704339e-15 | I19: Tc [K] | J19: 512.6 | L19: NIST | S19: cpB | T19: vypC
A20: xC | B20: =Kolona!AF49 -> 0.40811569 | C20: 0.50304965 | D20: 0 | S20: =A36+B36*S16+C36*S16^2+D36*S16^3 -> 89.701978 | T20: =0 -> 0
A21: xB | B21: =Kolona!AF50 -> 0.55569101 | C21: =1-C19-C20 -> 0.4950961 | D21: =(B18*B21-C18*C21)/D18 -> 0.81618511 | E21: =J10 -> 0.81618515 | F21: =(D21-E21)^2 -> 2.1667705e-15 | I21: MTBE | S21: cpC | T21: vypZ
A22: h[kJ/kmol/h] | B22: =S24*(B17-C17) -> 4198.0886 | C22: 0 | D22: =T22 -> 22245.414 | F22: odchylka | I22: A [kJ/mol] | J22: 46.23 | S22: =D43+E43*S16+S16^2*F43 -> 310.69912 | T22: =D19*T16+D21*T18 -> 22245.414
A23: H | B23: =B18*B22 -> 122344.34 | C23: 0 | D23: =D18*D22 -> 122344.24 | E23: =(B23-D23)/B23 -> 8.2063309e-07 | F23: =E23^2 -> 6.7343866e-13 | I23: beta | J23: 0.2893 | S23: cpZ
A24: kJ/h | F24: SUMA | I24: Tc [K] | J24: 497.1 | S24: =S18*B19+S20*B21+S22*B20 -> 183.43401
A25: Referenčný stav | F25: =F19+F21+F23 -> 6.7777587e-13 | K25: Majer, V.; Svoboda, V., Enthalpies of Vaporization of Organic Compounds: A Critical Review and Data Compilation, Blackwell Scientific Publications, Oxford, 1985, 300.
A26: L | C26: teplota L a G
A29: Metanol | C29: M | D29: 32.04 | E29: kg/kmol | K29: Andon, R.J.L.; Martin, J.F., Thermodynamic properties of organic oxygen compounds. 40. Heat capacity and entropy of six ethers, J. Chem. Thermodynam., 1975, 7, 593-606.
A30: cp | B30: kcal/kg/K | E30: 1kcal | F30: = | G30: 4,1868kJ
A31: a | B31: b | C31: c | D31: d
A32: 0.8382 | B32: =-3.231*10^-3 -> -0.003231 | C32: =8.296*10^-6 -> 8.296e-06 | D32: =-0.1689*10^-9 -> -1.689e-10
B33: kJ/kg/K
A34: =A32*4.1868 -> 3.5093758 | B34: =B32*4.1868 -> -0.013527551 | C34: =C32*4.1868 -> 3.4733693e-05 | D34: =D32*4.1868 -> -7.0715052e-10
B35: kJ/kmol/K
A36: =A34*$D$29 -> 112.4404 | B36: =B34*$D$29 -> -0.43342273 | C36: =C34*$D$29 -> 0.0011128675 | D36: =D34*$D$29 -> -2.2657103e-08
A39: [EMIM][HSO4] | F39: J/mol/K | G39: = | H39: kJ/kmol/K
A40: Ficke, L. E.; Novak, R.; Brennecke, J. F. (2010) J. Chem. Eng. Data 55(11),
A41: T | B41: cp[J/mol/K] | E41: cp
A42: 283.15 | B42: 290 | D42: a | E42: b | F42: c
A43: 293.15 | B43: 294 | D43: 753.28 | E43: -3.4195 | F43: 0.0063
A44: 303.15 | B44: 297
A45: 313.15 | B45: 302
A46: 323.15 | B46: 306
A47: 333.15 | B47: 313
...

Sheet Odparka-Extrakt
C1: Antoine equation parameters (P = Pa) | H1: i–j | I1: Δgij(kJ·mol−1) | J1: Δgji(kJ·mol−1) | K1: rmsd | L1: α | N1: R [kJ.mol^-1.K^-1] | O1: =8.314/1000 -> 0.008314
C2: A | D2: B | E2: C | I2: NRTL parameters
A3: A | B3: MTBE | C3: 20.84054 | D3: -2624.525 | E3: -46.15171 | H3: MTBE (1) + methanol (2) + [BMIM][HSO4] (3) at 318.15 K
A4: B | B4: Metanol | C4: 23.5347 | D4: -3661.468 | E4: -32.77001 | H4: 1–2 | I4: 5.5737 | J4: 7.4991 | K4: 0.0065 | L4: 0.4
A5: C | B5: [BMIM][HSO4] | C5: - | D5: - | E5: - | H5: 1–3 | I5: 19.2694 | J5: 16.212
A6: P[kPa] | B6: 2.45 | H6: 2–3 | I6: 10.6456 | J6: 0.5632
O8: Normalizacia
C9: t | D9: T | E9: PA0 | F9: PB0 | G9: PC0 | H9: KA | I9: KB | J9: KC | K9: xA | L9: xB | M9: xC | N9: SUMx | O9: xA | P9: xB | Q9: xC | T9: t | U9: T | V9: PA0 | W9: PB0 | X9: PC0 | Y9: KA | Z9: KB | AA9: KC | AB9: yA | AC9: yB | AD9: yC | AE9: SUMy | AF9: sumP
C10: 45.124085 | D10: 318.27409 | E10: 72.83051 | F10: 44.807306 | G10: 0 | H10: 16260.352 | I10: 49.810086 | J10: 0 | K10: =MMULT(L20,I20) -> 2.3429527e-07 | L10: =MMULT(L22,I22) -> 0.01999977 | M10: =MMULT(L24,I24) -> 0.98 | N10: =SUM(K10:M10) -> 1 | O10: =K10/(K10+L10+M10) -> 2.3429527e-07 | P10: =L10/(K10+L10+M10) -> 0.01999977 | Q10: =M10/(K10+L10+M10) -> 0.98 | T10: 45.124085 | U10: =T10+273.15 -> 318.27409 | V10: =EXP(C3+D3/(U10+E3))/1000 -> 72.83051 | W10: =EXP(C4+D4/(U10+E4))/1000 -> 44.807306 | X10: 0 | Y10: =V10*AA14/$B$6 -> 16260.352 | Z10: =W10*AB14/$B$6 -> 49.810086 | AA10: =X10*AC14/$B$6 -> 0 | AB10: =(O10*AA14*V10)/$B$6 -> 0.0038097237 | AC10: =(P10*AB14*W10)/$B$6 -> 0.99619027 | AD10: =(Q10*AC14*X10)/$B$6 -> 0 | AE10: =SUM(AB10:AD10) -> 0.99999999 | AF10: =V10*O10*AA14+W10*P10*AB14+Q10*X10*AC14 -> 2.45
C12: NASTRELY | AA12: Vypocitane
C13: γA | D13: γB | E13: γC | F13: τAB | G13: τBA | H13: τAC | I13: τCA | J13: τBC | K13: τCB | L13: GAB | M13: GBA | N13: GAC | O13: GCA | P13: GBC | Q13: GCB | R13: θ1 | S13: θ2 | T13: θ3 | U13: φ1 | V13: φ2 | W13: φ3 | X13: lnγA | Y13: lnγB | Z13: lnγC | AA13: γA | AB13: γB | AC13: γC
C14: 1 | D14: 1 | E14: 1 | F14: =I4/$O$1/$D$10 -> 2.1063585 | G14: =J4/$O$1/$D$10 -> 2.833987 | H14: =I5/$O$1/$D$10 -> 7.2821043 | I14: =J5/$O$1/$D$10 -> 6.1266814 | J14: =I6/$O$1/$D$10 -> 4.0230816 | K14: =J6/$O$1/$D$10 -> 0.21283907 | L14: =EXP(-$L$4*F14) -> 0.4306139 | M14: =EXP(-$L$4*G14) -> 0.32187411 | N14: =EXP(-$L$4*H14) -> 0.054321145 | O14: =EXP(-$L$4*I14) -> 0.086235568 | P14: =EXP(-$L$4*J14) -> 0.20004106 | Q14: =EXP(-$L$4*K14) -> 0.91838772 | R14: =P10*G14*M14+Q10*I14*O14 -> 0.53601462 | S14: =O10*F14*L14+Q10*K14*Q14 -> 0.19155962 | T14: =O10*H14*N14+P10*J14*P14 -> 0.016095538 | U14: =O10+M14*P10+Q10*O14 -> 0.090948499 | V14: =O10*L14+P10+Q10*Q14 -> 0.92001983 | W14: =O10*N14+P10*P14+Q10 -> 0.98400078 | X14: =R14/U14-O10*R14/U14^2+P10*L14/V14*(F14-S14/V14)+Q10*N14/W14*(H14-T14/W14) -> 6.3044381 | Y14: =S14/V14-P10*S14/V14^2+O10*M14/U14*(G14-R14/U14)+Q10*P14/W14*(J14-T14/W14) -> 1.0019343 | Z14: =T14/W14-Q10*T14/W14^2+O10*O14/U14*(I14-R14/U14)+P10*Q14/V14*(K14-S14/V14) -> 0.00015892397 | AA14: =EXP(X14) -> 546.99416 | AB14: =EXP(Y14) -> 2.7235449 | AC14: =EXP(Z14) -> 1.0001589
B19: n[kmol/h] | C19: xA | D19: xB | E19: xC | G19: A | I19: ps | K19: inverzna
A20: F | B20: =A32 -> 23.643117 | C20: =A33 -> 0.001854252 | D20: =A34 -> 0.4950961 | E20: =A35 -> 0.50304965 | H20: =$B$22+$B$21*H10 -> 187115.58 | I20: =$B$20*C20 -> 0.043840296 | L20: =MINVERSE(H20) -> 5.3442905e-06
A21: D | B21: =B20-B22 -> 11.506727 | C21: =AB10 -> 0.0038097237 | D21: =AC10 -> 0.99619027 | E21: =AD10 -> 0 | G21: B | I21: ps | K21: inverzna
A22: W | B22: =B20*E20/E22 -> 12.136389 | C22: =O10 -> 2.3429527e-07 | D22: =P10 -> 0.01999977 | E22: 0.98 | H22: =$B$22+$B$21*I10 -> 585.28747 | I22: =$B$20*D20 -> 11.705615 | L22: =MINVERSE(H22) -> 0.0017085621
G23: C | I23: ps | K23: inverzna
H24: =$B$22+$B$21*J10 -> 12.136389 | I24: =$B$20*E20 -> 11.893662 | L24: =MINVERSE(H24) -> 0.082396829
C28: t | D28: T | E28: PA0 | F28: PB0 | G28: PC0 | H28: xA | I28: xB | J28: xC | K28: τAB | L28: τBA | M28: τAC | N28: τCA | O28: τBC | P28: τCB | Q28: GAB | R28: GBA | S28: GAC | T28: GCA | U28: GBC | V28: GCB | W28: θ1 | X28: θ2 | Y28: θ3 | Z28: φ1 | AA28: φ2 | AB28: φ3 | AC28: lnγA | AD28: lnγB | AE28: lnγC | AF28: γA | AG28: γB | AH28: γC | AI28: PA | AJ28: PB | AK28: PC | AL28: P[kPa]
C29: 45 | D29: =C29+273.15 -> 318.15 | E29: =EXP(C3+D3/(D29+E3))/1000 -> 72.510769 | F29: =EXP(C4+D4/(D29+E4))/1000 -> 44.558146 | G29: 0 | H29: =C22 -> 2.3429527e-07 | I29: =D22 -> 0.01999977 | J29: =E22 -> 0.98 | K29: =I4/$O$1/$D$29 -> 2.10718 | L29: =J4/$O$1/$D$29 -> 2.8350923 | M29: =I5/$O$1/$D$29 -> 7.2849444 | N29: =J5/$O$1/$D$29 -> 6.1290709 | O29: =I6/$O$1/$D$29 -> 4.0246507 | P29: =J6/$O$1/$D$29 -> 0.21292208 | Q29: =EXP(-$L$4*K29) -> 0.43047242 | R29: =EXP(-$L$4*L29) -> 0.32173183 | S29: =EXP(-$L$4*M29) -> 0.054259468 | T29: =EXP(-$L$4*N29) -> 0.086153183 | U29: =EXP(-$L$4*O29) -> 0.19991554 | V29: =EXP(-$L$4*P29) -> 0.91835722 | W29: =I29*L29*R29+J29*N29*T29 -> 0.53572077 | X29: =H29*K29*Q29+J29*P29*V29 -> 0.19162797 | Y29: =H29*M29*S29+I29*O29*U29 -> 0.016091712 | Z29: =H29+R29*I29+J29*T29 -> 0.090864916 | AA29: =H29*Q29+I29+J29*V29 -> 0.91998995 | AB29: =H29*S29+I29*U29+J29 -> 0.98399828 | AC29: =W29/Z29-H29*W29/Z29^2+I29*Q29/AA29*(K29-X29/AA29)+J29*S29/AB29*(M29-Y29/AB29) -> 6.3063355 | AD29: =X29/AA29-I29*X29/AA29^2+H29*R29/Z29*(L29-W29/Z29)+J29*U29/AB29*(O29-Y29/AB29) -> 1.0018278 | AE29: =Y29/AB29-J29*Y29/AB29^2+H29*T29/Z29*(N29-W29/Z29)+I29*V29/AA29*(P29-X29/AA29) -> 0.00015890579 | AF29: =EXP(AC29) -> 548.03297 | AG29: =EXP(AD29) -> 2.7232549 | AH29: =EXP(AE29) -> 1.0001589 | AI29: =AF29*E29*H29 -> 0.009310494 | AJ29: =AG29*F29*I29 -> 2.4268359 | AK29: =AH29*G29*J29 -> 0 | AL29: =SUM(AI29:AK29) -> 2.4361464
A31: vstup | C31: vystup
A32: =SF!V2 -> 23.643117 | C32: =B22 -> 12.136389
A33: =SF!V3 -> 0.001854252 | C33: =C22 -> 2.3429527e-07
A34: =SF!V4 -> 0.4950961 | C34: =D22 -> 0.01999977
A35: =SF!V5 -> 0.50304965 | C35: =E22 -> 0.98

Sheet Odparka-Rafinat
C1: Antoine equation parameters (P = Pa) | H1: i–j | I1: Δgij(kJ·mol−1) | J1: Δgji(kJ·mol−1) | K1: rmsd | L1: α | N1: R [kJ.mol^-1.K^-1] | O1: =8.314/1000 -> 0.008314
C2: A | D2: B | E2: C | I2: NRTL parameters
A3: A | B3: MTBE | C3: 20.84054 | D3: -2624.525 | E3: -46.15171 | H3: MTBE (1) + methanol (2) + [BMIM][HSO4] (3) at 318.15 K
A4: B | B4: Metanol | C4: 23.5347 | D4: -3661.468 | E4: -32.77001 | H4: 1–2 | I4: 5.5737 | J4: 7.4991 | K4: 0.0065 | L4: 0.4
A5: C | B5: [BMIM][HSO4] | C5: - | D5: - | E5: - | H5: 1–3 | I5: 19.2694 | J5: 16.212
A6: P[kPa] | B6: 73.5 | H6: 2–3 | I6: 10.6456 | J6: 0.5632
O8: Normalizacia
C9: t | D9: T | E9: PA0 | F9: PB0 | G9: PC0 | H9: KA | I9: KB | J9: KC | K9: xA | L9: xB | M9: xC | N9: SUMx | O9: xA | P9: xB | Q9: xC | T9: t | U9: T | V9: PA0 | W9: PB0 | X9: PC0 | Y9: KA | Z9: KB | AA9: KC | AB9: yA | AC9: yB | AD9: yC | AE9: SUMy | AF9: sumP
C10: 45.04381 | D10: 318.19381 | E10: 72.623532 | F10: 44.645983 | G10: 0 | H10: 1.3302263 | I10: 8.7490645 | J10: 0 | K10: =MMULT(L20,I20) -> 0.7496859 | L10: =MMULT(L22,I22) -> 0.00031410579 | M10: =MMULT(L24,I24) -> 0.25 | N10: =SUM(K10:M10) -> 1 | O10: =K10/(K10+L10+M10) -> 0.7496859 | P10: =L10/(K10+L10+M10) -> 0.00031410579 | Q10: =M10/(K10+L10+M10) -> 0.25 | T10: 45.04381 | U10: =T10+273.15 -> 318.19381 | V10: =EXP(C3+D3/(U10+E3))/1000 -> 72.623532 | W10: =EXP(C4+D4/(U10+E4))/1000 -> 44.645983 | X10: 0 | Y10: =V10*AA14/$B$6 -> 1.3302263 | Z10: =W10*AB14/$B$6 -> 8.7490645 | AA10: =X10*AC14/$B$6 -> 0 | AB10: =(O10*AA14*V10)/$B$6 -> 0.99725186 | AC10: =(P10*AB14*W10)/$B$6 -> 0.0027481318 | AD10: =(Q10*AC14*X10)/$B$6 -> 0 | AE10: =SUM(AB10:AD10) -> 0.99999999 | AF10: =V10*AA14*O10+W10*AB14*P10 -> 73.499999
C12: NASTRELY | AA12: Vypocitane
C13: γA | D13: γB | E13: γC | F13: τAB | G13: τBA | H13: τAC | I13: τCA | J13: τBC | K13: τCB | L13: GAB | M13: GBA | N13: GAC | O13: GCA | P13: GBC | Q13: GCB | R13: θ1 | S13: θ2 | T13: θ3 | U13: φ1 | V13: φ2 | W13: φ3 | X13: lnγA | Y13: lnγB | Z13: lnγC | AA13: γA | AB13: γB | AC13: γC
C14: 1 | D14: 1 | E14: 1 | F14: =I4/$O$1/$D$10 -> 2.1068899 | G14: =J4/$O$1/$D$10 -> 2.8347019 | H14: =I5/$O$1/$D$10 -> 7.2839414 | I14: =J5/$O$1/$D$10 -> 6.1282271 | J14: =I6/$O$1/$D$10 -> 4.0240966 | K14: =J6/$O$1/$D$10 -> 0.21289276 | L14: =EXP(-$L$4*F14) -> 0.43052238 | M14: =EXP(-$L$4*G14) -> 0.32178207 | N14: =EXP(-$L$4*H14) -> 0.054281242 | O14: =EXP(-$L$4*I14) -> 0.086182269 | P14: =EXP(-$L$4*J14) -> 0.19995986 | Q14: =EXP(-$L$4*K14) -> 0.91836799 | R14: =P10*G14*M14+Q10*I14*O14 -> 0.13232264 | S14: =O10*F14*L14+Q10*K14*Q14 -> 0.72889101 | T14: =O10*H14*N14+P10*J14*P14 -> 0.2966646 | U14: =O10+M14*P10+Q10*O14 -> 0.77133254 | V14: =O10*L14+P10+Q10*Q14 -> 0.55266266 | W14: =O10*N14+P10*P14+Q10 -> 0.29075669 | X14: =R14/U14-O10*R14/U14^2+P10*L14/V14*(F14-S14/V14)+Q10*N14/W14*(H14-T14/W14) -> 0.29734545 | Y14: =S14/V14-P10*S14/V14^2+O10*M14/U14*(G14-R14/U14)+Q10*P14/W14*(J14-T14/W14) -> 2.6674679 | Z14: =T14/W14-Q10*T14/W14^2+O10*O14/U14*(I14-R14/U14)+P10*Q14/V14*(K14-S14/V14) -> 0.64139848 | AA14: =EXP(X14) -> 1.3462803 | AB14: =EXP(Y14) -> 14.403451 | AC14: =EXP(Z14) -> 1.8991349
B19: n | C19: xA | D19: xB | E19: xC | G19: A | I19: ps | K19: inverzna
A20: F | B20: =A31 -> 13.518522 | C20: =A32 -> 0.99678893 | D20: =A33 -> 0.0027435803 | E20: =A34 -> 0.00046748711 | H20: =$B$22+$B$21*H10 -> 17.974345 | I20: =$B$20*C20 -> 13.475113 | L20: =MINVERSE(H20) -> 0.055634852
A21: D | B21: =B20-B22 -> 13.493243 | C21: =AB10 -> 0.99725186 | D21: =AC10 -> 0.0027481318 | E21: =AD10 -> 0 | G21: B | I21: ps | K21: inverzna
A22: W | B22: =B20*E20/E22 -> 0.025278938 | C22: =O10 -> 0.7496859 | D22: =P10 -> 0.00031410579 | E22: 0.25 | H22: =$B$22+$B$21*I10 -> 118.07853 | I22: =$B$20*D20 -> 0.03708915 | L22: =MINVERSE(H22) -> 0.0084689402
G23: C | I23: ps | K23: inverzna
H24: =$B$22+$B$21*J10 -> 0.025278938 | I24: =$B$20*E20 -> 0.0063197346 | L24: =MINVERSE(H24) -> 39.558623
C28: t | D28: T | E28: PA0 | F28: PB0 | G28: PC0 | H28: xA | I28: xB | J28: xC | K28: τAB | L28: τBA | M28: τAC | N28: τCA | O28: τBC | P28: τCB | Q28: GAB | R28: GBA | S28: GAC | T28: GCA | U28: GBC | V28: GCB | W28: θ1 | X28: θ2 | Y28: θ3 | Z28: φ1 | AA28: φ2 | AB28: φ3 | AC28: lnγA | AD28: lnγB | AE28: lnγC | AF28: γA | AG28: γB | AH28: γC | AI28: PA | AJ28: PB | AK28: PC | AL28: P[kPa] | AM28: yA | AN28: yB | AO28: yC
C29: 45 | D29: =273.15+C29 -> 318.15 | E29: =EXP(C3+D3/(D29+E3))/1000 -> 72.510769 | F29: =EXP(C4+D4/(D29+E4))/1000 -> 44.558146 | G29: 0 | H29: =C22 -> 0.7496859 | I29: =D22 -> 0.00031410579 | J29: =E22 -> 0.25 | K29: =I4/$O$1/$D$29 -> 2.10718 | L29: =J4/$O$1/$D$29 -> 2.8350923 | M29: =I5/$O$1/$D$29 -> 7.2849444 | N29: =J5/$O$1/$D$29 -> 6.1290709 | O29: =I6/$O$1/$D$29 -> 4.0246507 | P29: =J6/$O$1/$D$29 -> 0.21292208 | Q29: =EXP(-$L$4*K29) -> 0.43047242 | R29: =EXP(-$L$4*L29) -> 0.32173183 | S29: =EXP(-$L$4*M29) -> 0.054259468 | T29: =EXP(-$L$4*N29) -> 0.086153183 | U29: =EXP(-$L$4*O29) -> 0.19991554 | V29: =EXP(-$L$4*P29) -> 0.91835722 | W29: =I29*L29*R29+J29*N29*T29 -> 0.13229625 | X29: =H29*K29*Q29+J29*P29*V29 -> 0.72891189 | Y29: =H29*M29*S29+I29*O29*U29 -> 0.29658648 | Z29: =H29+R29*I29+J29*T29 -> 0.77132525 | AA29: =H29*Q29+I29+J29*V29 -> 0.55262252 | AB29: =H29*S29+I29*U29+J29 -> 0.29074035 | AC29: =W29/Z29-H29*W29/Z29^2+I29*Q29/AA29*(K29-X29/AA29)+J29*S29/AB29*(M29-Y29/AB29) -> 0.29729881 | AD29: =X29/AA29-I29*X29/AA29^2+H29*R29/Z29*(L29-W29/Z29)+J29*U29/AB29*(O29-Y29/AB29) -> 2.6676575 | AE29: =Y29/AB29-J29*Y29/AB29^2+H29*T29/Z29*(N29-W29/Z29)+I29*V29/AA29*(P29-X29/AA29) -> 0.64122918 | AF29: =EXP(AC29) -> 1.3462175 | AG29: =EXP(AD29) -> 14.406184 | AH29: =EXP(AE29) -> 1.8988134 | AI29: =AF29*E29*H29 -> 73.180788 | AJ29: =AG29*F29*I29 -> 0.20162854 | AK29: =AH29*G29*J29 -> 0 | AL29: =SUM(AI29:AK29) -> 73.382417 | AM29: =AI29/AL29 -> 0.99725236 | AN29: =AJ29/AM29 -> 0.20218407 | AO29: =AK29/AN29 -> 0
A30: vstup | C30: vystup
A31: =Kolona!AG41 -> 13.518522 | C31: =B22 -> 0.025278938
A32: =Kolona!AG42 -> 0.99678893 | C32: =C22 -> 0.7496859
A33: =Kolona!AG43 -> 0.0027435803 | C33: =D22 -> 0.00031410579
A34: =Kolona!AG44 -> 0.00046748711 | C34: =E22 -> 0.25
